Workbook

Sheet CUT_LIST
A1: PROJECT NAME:
A2: DATE:
A3: ALUMINIUM FINISH:
A5: LABEL | B5: PROFILE | C5: CUT LENGTH (MM) | D5: QTY | E5: TOTAL LENGTH (MM) | F5: OFFCUT AVAILABLE? | G5: NUMBER OF OFFCUTS AVAILABLE | H5: IF YES (RAL) | J5: PROFILES REQUIRED
E6: =C6*D6 -> 0 | F6: NO | J6: {=IFERROR( INDEX($B$6:$B$1000, MATCH(0, IF($B$6:$B$1000<>"", COUNTIF($J$5:J5,$B$6:$B$1000), 1 ), 0) ), "")}
E7: =C7*D7 -> 0 | F7: NO | J7: {=IFERROR( INDEX($B$6:$B$1000, MATCH(0, IF($B$6:$B$1000<>"", COUNTIF($J$5:J6,$B$6:$B$1000), 1 ), 0) ), "")}
E8: =C8*D8 -> 0 | F8: NO | J8: {=IFERROR( INDEX($B$6:$B$1000, MATCH(0, IF($B$6:$B$1000<>"", COUNTIF($J$5:J7,$B$6:$B$1000), 1 ), 0) ), "")}
E9: =C9*D9 -> 0 | F9: NO | J9: {=IFERROR( INDEX($B$6:$B$1000, MATCH(0, IF($B$6:$B$1000<>"", COUNTIF($J$5:J8,$B$6:$B$1000), 1 ), 0) ), "")}
E10: =C10*D10 -> 0 | F10: NO | J10: {=IFERROR( INDEX($B$6:$B$1000, MATCH(0, IF($B$6:$B$1000<>"", COUNTIF($J$5:J9,$B$6:$B$1000), 1 ), 0) ), "")}
E11: =C11*D11 -> 0 | F11: NO | J11: {=IFERROR( INDEX($B$6:$B$1000, MATCH(0, IF($B$6:$B$1000<>"", COUNTIF($J$5:J10,$B$6:$B$1000), 1 ), 0) ), "")}
E12: =C12*D12 -> 0 | F12: NO | J12: {=IFERROR( INDEX($B$6:$B$1000, MATCH(0, IF($B$6:$B$1000<>"", COUNTIF($J$5:J11,$B$6:$B$1000), 1 ), 0) ), "")}
E13: =C13*D13 -> 0 | F13: NO | J13: {=IFERROR( INDEX($B$6:$B$1000, MATCH(0, IF($B$6:$B$1000<>"", COUNTIF($J$5:J12,$B$6:$B$1000), 1 ), 0) ), "")}
E14: =C14*D14 -> 0 | F14: NO | J14: {=IFERROR( INDEX($B$6:$B$1000, MATCH(0, IF($B$6:$B$1000<>"", COUNTIF($J$5:J13,$B$6:$B$1000), 1 ), 0) ), "")}
E15: =C15*D15 -> 0 | F15: NO | J15: {=IFERROR( INDEX($B$6:$B$1000, MATCH(0, IF($B$6:$B$1000<>"", COUNTIF($J$5:J14,$B$6:$B$1000), 1 ), 0) ), "")}
E16: =C16*D16 -> 0 | F16: NO | J16: {=IFERROR( INDEX($B$6:$B$1000, MATCH(0, IF($B$6:$B$1000<>"", COUNTIF($J$5:J15,$B$6:$B$1000), 1 ), 0) ), "")}
E17: =C17*D17 -> 0 | F17: NO | J17: {=IFERROR( INDEX($B$6:$B$1000, MATCH(0, IF($B$6:$B$1000<>"", COUNTIF($J$5:J16,$B$6:$B$1000), 1 ), 0) ), "")}
... E25: =C25*D25 -> 0 | F25: NO | J25: {=IFERROR( INDEX($B$6:$B$1000, MATCH(0, IF($B$6:$B$1000<>"", COUNTIF($J$5:J24,$B$6:$B$1000), 1 ), 0) ), "")}
E26: =C26*D26 -> 0 | F26: NO
E27: =C27*D27 -> 0 | F27: NO
E28: =C28*D28 -> 0 | F28: NO
E29: =C29*D29 -> 0 | F29: NO
E30: =C30*D30 -> 0 | F30: NO
E31: =C31*D31 -> 0 | F31: NO
E32: =C32*D32 -> 0 | F32: NO
E33: =C33*D33 -> 0 | F33: NO
E34: =C34*D34 -> 0 | F34: NO
E35: =C35*D35 -> 0 | F35: NO
E36: =C36*D36 -> 0 | F36: NO
E37: =C37*D37 -> 0 | F37: NO
... E528: =C528*D528 -> 0 | F528: NO

Sheet SUMMARY
A1: PROJECT NAME: | B1: =CUT_LIST!B1 -> 0
A2: DATE: | B2: =CUT_LIST!B2 -> 0
A4: SYSTEM CALCULATED
A5: PROFILE | B5: TOTAL LENGTH (MM) | C5: NO. OF LENGTHS REQUIRED | D5: ESTIMATED TOTAL WASTEAGE (MM) | E5: % WASTEAGE | G5: LENGTH SIZE (MM)
A6: =CUT_LIST!J6 | B6: {=SUMPRODUCT((CUT_LIST!$B$6:$B$1000=$A6)*IFERROR(CUT_LIST!$C$6:$C$1000,0)*(IFERROR(CUT_LIST!$D$6:$D$1000,0)-IF(UPPER(CUT_LIST!$F$6:$F$1000)="YES",IFERROR(IF(CUT_LIST!$G$6:$G$1000>IFERROR(CUT_LIST!$D$6:$D$1000,0),IFERROR(CUT_LIST!$D$6:$D$1000,0),CUT_LIST!$G$6:$G$1000),0),0)))} -> 0 | C6: =ROUNDUP(B6/$G$6,0) -> 0 | D6: =C6*$G$6-B6 -> 0 | E6: =(D6/($G$6*C6))*0.6 -> #DIV/0! | G6: 6400
A7: =CUT_LIST!J7 | B7: {=SUMPRODUCT((CUT_LIST!$B$6:$B$1000=$A7)*IFERROR(CUT_LIST!$C$6:$C$1000,0)*(IFERROR(CUT_LIST!$D$6:$D$1000,0)-IF(UPPER(CUT_LIST!$F$6:$F$1000)="YES",IFERROR(IF(CUT_LIST!$G$6:$G$1000>IFERROR(CUT_LIST!$D$6:$D$1000,0),IFERROR(CUT_LIST!$D$6:$D$1000,0),CUT_LIST!$G$6:$G$1000),0),0)))} -> 0 | C7: =ROUNDUP(B7/$G$6,0) -> 0 | D7: =C7*$G$6-B7 -> 0 | E7: =(D7/($G$6*C7))*0.6 -> #DIV/0!
A8: =CUT_LIST!J8 | B8: {=SUMPRODUCT((CUT_LIST!$B$6:$B$1000=$A8)*IFERROR(CUT_LIST!$C$6:$C$1000,0)*(IFERROR(CUT_LIST!$D$6:$D$1000,0)-IF(UPPER(CUT_LIST!$F$6:$F$1000)="YES",IFERROR(IF(CUT_LIST!$G$6:$G$1000>IFERROR(CUT_LIST!$D$6:$D$1000,0),IFERROR(CUT_LIST!$D$6:$D$1000,0),CUT_LIST!$G$6:$G$1000),0),0)))} -> 0 | C8: =ROUNDUP(B8/$G$6,0) -> 0 | D8: =C8*$G$6-B8 -> 0 | E8: =(D8/($G$6*C8))*0.6 -> #DIV/0!
A9: =CUT_LIST!J9 | B9: {=SUMPRODUCT((CUT_LIST!$B$6:$B$1000=$A9)*IFERROR(CUT_LIST!$C$6:$C$1000,0)*(IFERROR(CUT_LIST!$D$6:$D$1000,0)-IF(UPPER(CUT_LIST!$F$6:$F$1000)="YES",IFERROR(IF(CUT_LIST!$G$6:$G$1000>IFERROR(CUT_LIST!$D$6:$D$1000,0),IFERROR(CUT_LIST!$D$6:$D$1000,0),CUT_LIST!$G$6:$G$1000),0),0)))} -> 0 | C9: =ROUNDUP(B9/$G$6,0) -> 0 | D9: =C9*$G$6-B9 -> 0 | E9: =(D9/($G$6*C9))*0.6 -> #DIV/0!
A10: =CUT_LIST!J10 | B10: {=SUMPRODUCT((CUT_LIST!$B$6:$B$1000=$A10)*IFERROR(CUT_LIST!$C$6:$C$1000,0)*(IFERROR(CUT_LIST!$D$6:$D$1000,0)-IF(UPPER(CUT_LIST!$F$6:$F$1000)="YES",IFERROR(IF(CUT_LIST!$G$6:$G$1000>IFERROR(CUT_LIST!$D$6:$D$1000,0),IFERROR(CUT_LIST!$D$6:$D$1000,0),CUT_LIST!$G$6:$G$1000),0),0)))} -> 0 | C10: =ROUNDUP(B10/$G$6,0) -> 0 | D10: =C10*$G$6-B10 -> 0 | E10: =(D10/($G$6*C10))*0.6 -> #DIV/0!
A11: =CUT_LIST!J11 | B11: {=SUMPRODUCT((CUT_LIST!$B$6:$B$1000=$A11)*IFERROR(CUT_LIST!$C$6:$C$1000,0)*(IFERROR(CUT_LIST!$D$6:$D$1000,0)-IF(UPPER(CUT_LIST!$F$6:$F$1000)="YES",IFERROR(IF(CUT_LIST!$G$6:$G$1000>IFERROR(CUT_LIST!$D$6:$D$1000,0),IFERROR(CUT_LIST!$D$6:$D$1000,0),CUT_LIST!$G$6:$G$1000),0),0)))} -> 0 | C11: =ROUNDUP(B11/$G$6,0) -> 0 | D11: =C11*$G$6-B11 -> 0 | E11: =(D11/($G$6*C11))*0.6 -> #DIV/0!
A12: =CUT_LIST!J12 | B12: {=SUMPRODUCT((CUT_LIST!$B$6:$B$1000=$A12)*IFERROR(CUT_LIST!$C$6:$C$1000,0)*(IFERROR(CUT_LIST!$D$6:$D$1000,0)-IF(UPPER(CUT_LIST!$F$6:$F$1000)="YES",IFERROR(IF(CUT_LIST!$G$6:$G$1000>IFERROR(CUT_LIST!$D$6:$D$1000,0),IFERROR(CUT_LIST!$D$6:$D$1000,0),CUT_LIST!$G$6:$G$1000),0),0)))} -> 0 | C12: =ROUNDUP(B12/$G$6,0) -> 0 | D12: =C12*$G$6-B12 -> 0 | E12: =(D12/($G$6*C12))*0.6 -> #DIV/0!
A13: =CUT_LIST!J13 | B13: {=SUMPRODUCT((CUT_LIST!$B$6:$B$1000=$A13)*IFERROR(CUT_LIST!$C$6:$C$1000,0)*(IFERROR(CUT_LIST!$D$6:$D$1000,0)-IF(UPPER(CUT_LIST!$F$6:$F$1000)="YES",IFERROR(IF(CUT_LIST!$G$6:$G$1000>IFERROR(CUT_LIST!$D$6:$D$1000,0),IFERROR(CUT_LIST!$D$6:$D$1000,0),CUT_LIST!$G$6:$G$1000),0),0)))} -> 0 | C13: =ROUNDUP(B13/$G$6,0) -> 0 | D13: =C13*$G$6-B13 -> 0 | E13: =(D13/($G$6*C13))*0.6 -> #DIV/0!
A14: =CUT_LIST!J14 | B14: {=SUMPRODUCT((CUT_LIST!$B$6:$B$1000=$A14)*IFERROR(CUT_LIST!$C$6:$C$1000,0)*(IFERROR(CUT_LIST!$D$6:$D$1000,0)-IF(UPPER(CUT_LIST!$F$6:$F$1000)="YES",IFERROR(IF(CUT_LIST!$G$6:$G$1000>IFERROR(CUT_LIST!$D$6:$D$1000,0),IFERROR(CUT_LIST!$D$6:$D$1000,0),CUT_LIST!$G$6:$G$1000),0),0)))} -> 0 | C14: =ROUNDUP(B14/$G$6,0) -> 0 | D14: =C14*$G$6-B14 -> 0 | E14: =(D14/($G$6*C14))*0.6 -> #DIV/0!
A15: =CUT_LIST!J15 | B15: {=SUMPRODUCT((CUT_LIST!$B$6:$B$1000=$A15)*IFERROR(CUT_LIST!$C$6:$C$1000,0)*(IFERROR(CUT_LIST!$D$6:$D$1000,0)-IF(UPPER(CUT_LIST!$F$6:$F$1000)="YES",IFERROR(IF(CUT_LIST!$G$6:$G$1000>IFERROR(CUT_LIST!$D$6:$D$1000,0),IFERROR(CUT_LIST!$D$6:$D$1000,0),CUT_LIST!$G$6:$G$1000),0),0)))} -> 0 | C15: =ROUNDUP(B15/$G$6,0) -> 0 | D15: =C15*$G$6-B15 -> 0 | E15: =(D15/($G$6*C15))*0.6 -> #DIV/0!
A16: =CUT_LIST!J16 | B16: {=SUMPRODUCT((CUT_LIST!$B$6:$B$1000=$A16)*IFERROR(CUT_LIST!$C$6:$C$1000,0)*(IFERROR(CUT_LIST!$D$6:$D$1000,0)-IF(UPPER(CUT_LIST!$F$6:$F$1000)="YES",IFERROR(IF(CUT_LIST!$G$6:$G$1000>IFERROR(CUT_LIST!$D$6:$D$1000,0),IFERROR(CUT_LIST!$D$6:$D$1000,0),CUT_LIST!$G$6:$G$1000),0),0)))} -> 0 | C16: =ROUNDUP(B16/$G$6,0) -> 0 | D16: =C16*$G$6-B16 -> 0 | E16: =(D16/($G$6*C16))*0.6 -> #DIV/0!
A17: =CUT_LIST!J17 | B17: {=SUMPRODUCT((CUT_LIST!$B$6:$B$1000=$A17)*IFERROR(CUT_LIST!$C$6:$C$1000,0)*(IFERROR(CUT_LIST!$D$6:$D$1000,0)-IF(UPPER(CUT_LIST!$F$6:$F$1000)="YES",IFERROR(IF(CUT_LIST!$G$6:$G$1000>IFERROR(CUT_LIST!$D$6:$D$1000,0),IFERROR(CUT_LIST!$D$6:$D$1000,0),CUT_LIST!$G$6:$G$1000),0),0)))} -> 0 | C17: =ROUNDUP(B17/$G$6,0) -> 0 | D17: =C17*$G$6-B17 -> 0 | E17: =(D17/($G$6*C17))*0.6 -> #DIV/0!
A18: =CUT_LIST!J18 | B18: {=SUMPRODUCT((CUT_LIST!$B$6:$B$1000=$A18)*IFERROR(CUT_LIST!$C$6:$C$1000,0)*(IFERROR(CUT_LIST!$D$6:$D$1000,0)-IF(UPPER(CUT_LIST!$F$6:$F$1000)="YES",IFERROR(IF(CUT_LIST!$G$6:$G$1000>IFERROR(CUT_LIST!$D$6:$D$1000,0),IFERROR(CUT_LIST!$D$6:$D$1000,0),CUT_LIST!$G$6:$G$1000),0),0)))} -> 0 | C18: =ROUNDUP(B18/$G$6,0) -> 0 | D18: =C18*$G$6-B18 -> 0 | E18: =(D18/($G$6*C18))*0.6 -> #DIV/0!
... A25: =CUT_LIST!J25 | B25: {=SUMPRODUCT((CUT_LIST!$B$6:$B$1000=$A25)*IFERROR(CUT_LIST!$C$6:$C$1000,0)*(IFERROR(CUT_LIST!$D$6:$D$1000,0)-IF(UPPER(CUT_LIST!$F$6:$F$1000)="YES",IFERROR(IF(CUT_LIST!$G$6:$G$1000>IFERROR(CUT_LIST!$D$6:$D$1000,0),IFERROR(CUT_LIST!$D$6:$D$1000,0),CUT_LIST!$G$6:$G$1000),0),0)))} -> 0 | C25: =ROUNDUP(B25/$G$6,0) -> 0 | D25: =C25*$G$6-B25 -> 0 | E25: =(D25/($G$6*C25))*0.6 -> #DIV/0!
A26: MANUAL ORDER | G26: LENGTH SIZE (MM)
A27: PROFILE | B27: LENGTH SIZE | C27: NO. OF LENGTHS REQUIRED | G27: 6400
B28: =$G$27 -> 6400
B29: =$G$27 -> 6400
B30: =$G$27 -> 6400
B31: =$G$27 -> 6400
B32: =$G$27 -> 6400
B33: =$G$27 -> 6400
B34: =$G$27 -> 6400
B35: =$G$27 -> 6400
B36: =$G$27 -> 6400
B37: =$G$27 -> 6400
B38: =$G$27 -> 6400
B39: =$G$27 -> 6400
... B47: =$G$27 -> 6400

Sheet CUTTING LIST - OFFCUTS
A1: CUTTING LIST - FROM OFFCUTS
A2: PROJECT NAME: | B2: =CUT_LIST!B1 -> 0
A3: DATE: | B3: =CUT_LIST!B2 -> 0
A4: ALUMINIUM FINISH: | B4: =CUT_LIST!B3 -> 0
A6: LABEL | B6: PROFILE | C6: CUT LENGTH (MM) | D6: QTY | E6: RAL OF OFFCUT
A7: {=IF($F7="","",INDEX(CUT_LIST!$A$6:$A$1000,$F7))} | B7: {=IF($F7="","",INDEX(CUT_LIST!$B$6:$B$1000,$F7))} | C7: {=IF($F7="","",INDEX(CUT_LIST!$C$6:$C$1000,$F7))} | D7: =IF($F7="","", MIN( INDEX(CUT_LIST!$D$6:$D$1000,$F7), N(INDEX(CUT_LIST!$G$6:$G$1000,$F7)) ) ) | E7: {=IF($F7="","",INDEX(CUT_LIST!$H$6:$H$1000,$F7))} | F7: {=IFERROR( SMALL( IF( (TRIM(UPPER(CUT_LIST!$F$6:$F$1000))="YES")*(N(CUT_LIST!$G$6:$G$1000)>0), ROW(CUT_LIST!$F$6:$F$1000)-ROW(CUT_LIST!$F$6)+1 ), ROWS($F$7:F7) ), "")}
A8: {=IF($F8="","",INDEX(CUT_LIST!$A$6:$A$1000,$F8))} | B8: {=IF($F8="","",INDEX(CUT_LIST!$B$6:$B$1000,$F8))} | C8: {=IF($F8="","",INDEX(CUT_LIST!$C$6:$C$1000,$F8))} | D8: =IF($F8="","", MIN( INDEX(CUT_LIST!$D$6:$D$1000,$F8), N(INDEX(CUT_LIST!$G$6:$G$1000,$F8)) ) ) | E8: {=IF($F8="","",INDEX(CUT_LIST!$H$6:$H$1000,$F8))} | F8: {=IFERROR( SMALL( IF( (TRIM(UPPER(CUT_LIST!$F$6:$F$1000))="YES")*(N(CUT_LIST!$G$6:$G$1000)>0), ROW(CUT_LIST!$F$6:$F$1000)-ROW(CUT_LIST!$F$6)+1 ), ROWS($F$7:F8) ), "")}
A9: {=IF($F9="","",INDEX(CUT_LIST!$A$6:$A$1000,$F9))} | B9: {=IF($F9="","",INDEX(CUT_LIST!$B$6:$B$1000,$F9))} | C9: {=IF($F9="","",INDEX(CUT_LIST!$C$6:$C$1000,$F9))} | D9: =IF($F9="","", MIN( INDEX(CUT_LIST!$D$6:$D$1000,$F9), N(INDEX(CUT_LIST!$G$6:$G$1000,$F9)) ) ) | E9: {=IF($F9="","",INDEX(CUT_LIST!$H$6:$H$1000,$F9))} | F9: {=IFERROR( SMALL( IF( (TRIM(UPPER(CUT_LIST!$F$6:$F$1000))="YES")*(N(CUT_LIST!$G$6:$G$1000)>0), ROW(CUT_LIST!$F$6:$F$1000)-ROW(CUT_LIST!$F$6)+1 ), ROWS($F$7:F9) ), "")}
A10: {=IF($F10="","",INDEX(CUT_LIST!$A$6:$A$1000,$F10))} | B10: {=IF($F10="","",INDEX(CUT_LIST!$B$6:$B$1000,$F10))} | C10: {=IF($F10="","",INDEX(CUT_LIST!$C$6:$C$1000,$F10))} | D10: =IF($F10="","", MIN( INDEX(CUT_LIST!$D$6:$D$1000,$F10), N(INDEX(CUT_LIST!$G$6:$G$1000,$F10)) ) ) | E10: {=IF($F10="","",INDEX(CUT_LIST!$H$6:$H$1000,$F10))} | F10: {=IFERROR( SMALL( IF( (TRIM(UPPER(CUT_LIST!$F$6:$F$1000))="YES")*(N(CUT_LIST!$G$6:$G$1000)>0), ROW(CUT_LIST!$F$6:$F$1000)-ROW(CUT_LIST!$F$6)+1 ), ROWS($F$7:F10) ), "")}
A11: {=IF($F11="","",INDEX(CUT_LIST!$A$6:$A$1000,$F11))} | B11: {=IF($F11="","",INDEX(CUT_LIST!$B$6:$B$1000,$F11))} | C11: {=IF($F11="","",INDEX(CUT_LIST!$C$6:$C$1000,$F11))} | D11: =IF($F11="","", MIN( INDEX(CUT_LIST!$D$6:$D$1000,$F11), N(INDEX(CUT_LIST!$G$6:$G$1000,$F11)) ) ) | E11: {=IF($F11="","",INDEX(CUT_LIST!$H$6:$H$1000,$F11))} | F11: {=IFERROR( SMALL( IF( (TRIM(UPPER(CUT_LIST!$F$6:$F$1000))="YES")*(N(CUT_LIST!$G$6:$G$1000)>0), ROW(CUT_LIST!$F$6:$F$1000)-ROW(CUT_LIST!$F$6)+1 ), ROWS($F$7:F11) ), "")}
A12: {=IF($F12="","",INDEX(CUT_LIST!$A$6:$A$1000,$F12))} | B12: {=IF($F12="","",INDEX(CUT_LIST!$B$6:$B$1000,$F12))} | C12: {=IF($F12="","",INDEX(CUT_LIST!$C$6:$C$1000,$F12))} | D12: =IF($F12="","", MIN( INDEX(CUT_LIST!$D$6:$D$1000,$F12), N(INDEX(CUT_LIST!$G$6:$G$1000,$F12)) ) ) | E12: {=IF($F12="","",INDEX(CUT_LIST!$H$6:$H$1000,$F12))} | F12: {=IFERROR( SMALL( IF( (TRIM(UPPER(CUT_LIST!$F$6:$F$1000))="YES")*(N(CUT_LIST!$G$6:$G$1000)>0), ROW(CUT_LIST!$F$6:$F$1000)-ROW(CUT_LIST!$F$6)+1 ), ROWS($F$7:F12) ), "")}
A13: {=IF($F13="","",INDEX(CUT_LIST!$A$6:$A$1000,$F13))} | B13: {=IF($F13="","",INDEX(CUT_LIST!$B$6:$B$1000,$F13))} | C13: {=IF($F13="","",INDEX(CUT_LIST!$C$6:$C$1000,$F13))} | D13: =IF($F13="","", MIN( INDEX(CUT_LIST!$D$6:$D$1000,$F13), N(INDEX(CUT_LIST!$G$6:$G$1000,$F13)) ) ) | E13: {=IF($F13="","",INDEX(CUT_LIST!$H$6:$H$1000,$F13))} | F13: {=IFERROR( SMALL( IF( (TRIM(UPPER(CUT_LIST!$F$6:$F$1000))="YES")*(N(CUT_LIST!$G$6:$G$1000)>0), ROW(CUT_LIST!$F$6:$F$1000)-ROW(CUT_LIST!$F$6)+1 ), ROWS($F$7:F13) ), "")}
A14: {=IF($F14="","",INDEX(CUT_LIST!$A$6:$A$1000,$F14))} | B14: {=IF($F14="","",INDEX(CUT_LIST!$B$6:$B$1000,$F14))} | C14: {=IF($F14="","",INDEX(CUT_LIST!$C$6:$C$1000,$F14))} | D14: =IF($F14="","", MIN( INDEX(CUT_LIST!$D$6:$D$1000,$F14), N(INDEX(CUT_LIST!$G$6:$G$1000,$F14)) ) ) | E14: {=IF($F14="","",INDEX(CUT_LIST!$H$6:$H$1000,$F14))} | F14: {=IFERROR( SMALL( IF( (TRIM(UPPER(CUT_LIST!$F$6:$F$1000))="YES")*(N(CUT_LIST!$G$6:$G$1000)>0), ROW(CUT_LIST!$F$6:$F$1000)-ROW(CUT_LIST!$F$6)+1 ), ROWS($F$7:F14) ), "")}
A15: {=IF($F15="","",INDEX(CUT_LIST!$A$6:$A$1000,$F15))} | B15: {=IF($F15="","",INDEX(CUT_LIST!$B$6:$B$1000,$F15))} | C15: {=IF($F15="","",INDEX(CUT_LIST!$C$6:$C$1000,$F15))} | D15: =IF($F15="","", MIN( INDEX(CUT_LIST!$D$6:$D$1000,$F15), N(INDEX(CUT_LIST!$G$6:$G$1000,$F15)) ) ) | E15: {=IF($F15="","",INDEX(CUT_LIST!$H$6:$H$1000,$F15))} | F15: {=IFERROR( SMALL( IF( (TRIM(UPPER(CUT_LIST!$F$6:$F$1000))="YES")*(N(CUT_LIST!$G$6:$G$1000)>0), ROW(CUT_LIST!$F$6:$F$1000)-ROW(CUT_LIST!$F$6)+1 ), ROWS($F$7:F15) ), "")}
A16: {=IF($F16="","",INDEX(CUT_LIST!$A$6:$A$1000,$F16))} | B16: {=IF($F16="","",INDEX(CUT_LIST!$B$6:$B$1000,$F16))} | C16: {=IF($F16="","",INDEX(CUT_LIST!$C$6:$C$1000,$F16))} | D16: =IF($F16="","", MIN( INDEX(CUT_LIST!$D$6:$D$1000,$F16), N(INDEX(CUT_LIST!$G$6:$G$1000,$F16)) ) ) | E16: {=IF($F16="","",INDEX(CUT_LIST!$H$6:$H$1000,$F16))} | F16: {=IFERROR( SMALL( IF( (TRIM(UPPER(CUT_LIST!$F$6:$F$1000))="YES")*(N(CUT_LIST!$G$6:$G$1000)>0), ROW(CUT_LIST!$F$6:$F$1000)-ROW(CUT_LIST!$F$6)+1 ), ROWS($F$7:F16) ), "")}
A17: {=IF($F17="","",INDEX(CUT_LIST!$A$6:$A$1000,$F17))} | B17: {=IF($F17="","",INDEX(CUT_LIST!$B$6:$B$1000,$F17))} | C17: {=IF($F17="","",INDEX(CUT_LIST!$C$6:$C$1000,$F17))} | D17: =IF($F17="","", MIN( INDEX(CUT_LIST!$D$6:$D$1000,$F17), N(INDEX(CUT_LIST!$G$6:$G$1000,$F17)) ) ) | E17: {=IF($F17="","",INDEX(CUT_LIST!$H$6:$H$1000,$F17))} | F17: {=IFERROR( SMALL( IF( (TRIM(UPPER(CUT_LIST!$F$6:$F$1000))="YES")*(N(CUT_LIST!$G$6:$G$1000)>0), ROW(CUT_LIST!$F$6:$F$1000)-ROW(CUT_LIST!$F$6)+1 ), ROWS($F$7:F17) ), "")}
A18: {=IF($F18="","",INDEX(CUT_LIST!$A$6:$A$1000,$F18))} | B18: {=IF($F18="","",INDEX(CUT_LIST!$B$6:$B$1000,$F18))} | C18: {=IF($F18="","",INDEX(CUT_LIST!$C$6:$C$1000,$F18))} | D18: =IF($F18="","", MIN( INDEX(CUT_LIST!$D$6:$D$1000,$F18), N(INDEX(CUT_LIST!$G$6:$G$1000,$F18)) ) ) | E18: {=IF($F18="","",INDEX(CUT_LIST!$H$6:$H$1000,$F18))} | F18: {=IFERROR( SMALL( IF( (TRIM(UPPER(CUT_LIST!$F$6:$F$1000))="YES")*(N(CUT_LIST!$G$6:$G$1000)>0), ROW(CUT_LIST!$F$6:$F$1000)-ROW(CUT_LIST!$F$6)+1 ), ROWS($F$7:F18) ), "")}
... A1884: {=IF($F1884="","",INDEX(CUT_LIST!$A$6:$A$1000,$F1884))} | B1884: {=IF($F1884="","",INDEX(CUT_LIST!$B$6:$B$1000,$F1884))} | C1884: {=IF($F1884="","",INDEX(CUT_LIST!$C$6:$C$1000,$F1884))} | D1884: =IF($F1884="","", MIN( INDEX(CUT_LIST!$D$6:$D$1000,$F1884), N(INDEX(CUT_LIST!$G$6:$G$1000,$F1884)) ) ) | E1884: {=IF($F1884="","",INDEX(CUT_LIST!$H$6:$H$1000,$F1884))} | F1884: {=IFERROR( SMALL( IF( (TRIM(UPPER(CUT_LIST!$F$6:$F$1000))="YES")*(N(CUT_LIST!$G$6:$G$1000)>0), ROW(CUT_LIST!$F$6:$F$1000)-ROW(CUT_LIST!$F$6)+1 ), ROWS($F$7:F1884) ), "")}

Sheet CUTTING LIST - LENGTHS
A1: CUTTING LIST - LENGTHS
A2: PROJECT NAME: | B2: =CUT_LIST!B1 -> 0
A3: DATE: | B3: =CUT_LIST!B2 -> 0
A4: ALUMINIUM FINISH: | B4: =CUT_LIST!B3 -> 0
A6: LABEL | B6: PROFILE | C6: CUT LENGTH (MM) | D6: QTY
A7: {=IF($F7="","",INDEX(CUT_LIST!$A$6:$A$1000,$F7))} -> 0 | B7: {=IF($F7="","",INDEX(CUT_LIST!$B$6:$B$1000,$F7))} -> 0 | C7: {=IF($F7="","",INDEX(CUT_LIST!$C$6:$C$1000,$F7))} -> 0 | D7: {=IF($F7="","", IF( TRIM(UPPER(INDEX(CUT_LIST!$F$6:$F$1000,$F7)))="NO", N(INDEX(CUT_LIST!$D$6:$D$1000,$F7)), N(INDEX(CUT_LIST!$D$6:$D$1000,$F7))- MIN( N(INDEX(CUT_LIST!$D$6:$D$1000,$F7)), N(INDEX(CUT_LIST!$G$6:$G$1000,$F7)) ) ) )} -> 0 | F7: {=IFERROR( SMALL( IF( ( (TRIM(UPPER(CUT_LIST!$F$6:$F$1000))="NO") + (TRIM(UPPER(CUT_LIST!$F$6:$F$1000))="YES")* (N(CUT_LIST!$D$6:$D$1000)-MIN(N(CUT_LIST!$D$6:$D$1000),N(CUT_LIST!$G$6:$G$1000))>0) )>0, ROW(CUT_LIST!$F$6:$F$1000)-ROW(CUT_LIST!$F$6)+1 ), ROWS($F$7:F7) ), "")} -> 1
A8: {=IF($F8="","",INDEX(CUT_LIST!$A$6:$A$1000,$F8))} -> 0 | B8: {=IF($F8="","",INDEX(CUT_LIST!$B$6:$B$1000,$F8))} -> 0 | C8: {=IF($F8="","",INDEX(CUT_LIST!$C$6:$C$1000,$F8))} -> 0 | D8: {=IF($F8="","", IF( TRIM(UPPER(INDEX(CUT_LIST!$F$6:$F$1000,$F8)))="NO", N(INDEX(CUT_LIST!$D$6:$D$1000,$F8)), N(INDEX(CUT_LIST!$D$6:$D$1000,$F8))- MIN( N(INDEX(CUT_LIST!$D$6:$D$1000,$F8)), N(INDEX(CUT_LIST!$G$6:$G$1000,$F8)) ) ) )} -> 0 | F8: {=IFERROR( SMALL( IF( ( (TRIM(UPPER(CUT_LIST!$F$6:$F$1000))="NO") + (TRIM(UPPER(CUT_LIST!$F$6:$F$1000))="YES")* (N(CUT_LIST!$D$6:$D$1000)-MIN(N(CUT_LIST!$D$6:$D$1000),N(CUT_LIST!$G$6:$G$1000))>0) )>0, ROW(CUT_LIST!$F$6:$F$1000)-ROW(CUT_LIST!$F$6)+1 ), ROWS($F$7:F8) ), "")} -> 2
A9: {=IF($F9="","",INDEX(CUT_LIST!$A$6:$A$1000,$F9))} -> 0 | B9: {=IF($F9="","",INDEX(CUT_LIST!$B$6:$B$1000,$F9))} -> 0 | C9: {=IF($F9="","",INDEX(CUT_LIST!$C$6:$C$1000,$F9))} -> 0 | D9: {=IF($F9="","", IF( TRIM(UPPER(INDEX(CUT_LIST!$F$6:$F$1000,$F9)))="NO", N(INDEX(CUT_LIST!$D$6:$D$1000,$F9)), N(INDEX(CUT_LIST!$D$6:$D$1000,$F9))- MIN( N(INDEX(CUT_LIST!$D$6:$D$1000,$F9)), N(INDEX(CUT_LIST!$G$6:$G$1000,$F9)) ) ) )} -> 0 | F9: {=IFERROR( SMALL( IF( ( (TRIM(UPPER(CUT_LIST!$F$6:$F$1000))="NO") + (TRIM(UPPER(CUT_LIST!$F$6:$F$1000))="YES")* (N(CUT_LIST!$D$6:$D$1000)-MIN(N(CUT_LIST!$D$6:$D$1000),N(CUT_LIST!$G$6:$G$1000))>0) )>0, ROW(CUT_LIST!$F$6:$F$1000)-ROW(CUT_LIST!$F$6)+1 ), ROWS($F$7:F9) ), "")} -> 3
A10: {=IF($F10="","",INDEX(CUT_LIST!$A$6:$A$1000,$F10))} -> 0 | B10: {=IF($F10="","",INDEX(CUT_LIST!$B$6:$B$1000,$F10))} -> 0 | C10: {=IF($F10="","",INDEX(CUT_LIST!$C$6:$C$1000,$F10))} -> 0 | D10: {=IF($F10="","", IF( TRIM(UPPER(INDEX(CUT_LIST!$F$6:$F$1000,$F10)))="NO", N(INDEX(CUT_LIST!$D$6:$D$1000,$F10)), N(INDEX(CUT_LIST!$D$6:$D$1000,$F10))- MIN( N(INDEX(CUT_LIST!$D$6:$D$1000,$F10)), N(INDEX(CUT_LIST!$G$6:$G$1000,$F10)) ) ) )} -> 0 | F10: {=IFERROR( SMALL( IF( ( (TRIM(UPPER(CUT_LIST!$F$6:$F$1000))="NO") + (TRIM(UPPER(CUT_LIST!$F$6:$F$1000))="YES")* (N(CUT_LIST!$D$6:$D$1000)-MIN(N(CUT_LIST!$D$6:$D$1000),N(CUT_LIST!$G$6:$G$1000))>0) )>0, ROW(CUT_LIST!$F$6:$F$1000)-ROW(CUT_LIST!$F$6)+1 ), ROWS($F$7:F10) ), "")} -> 4
A11: {=IF($F11="","",INDEX(CUT_LIST!$A$6:$A$1000,$F11))} -> 0 | B11: {=IF($F11="","",INDEX(CUT_LIST!$B$6:$B$1000,$F11))} -> 0 | C11: {=IF($F11="","",INDEX(CUT_LIST!$C$6:$C$1000,$F11))} -> 0 | D11: {=IF($F11="","", IF( TRIM(UPPER(INDEX(CUT_LIST!$F$6:$F$1000,$F11)))="NO", N(INDEX(CUT_LIST!$D$6:$D$1000,$F11)), N(INDEX(CUT_LIST!$D$6:$D$1000,$F11))- MIN( N(INDEX(CUT_LIST!$D$6:$D$1000,$F11)), N(INDEX(CUT_LIST!$G$6:$G$1000,$F11)) ) ) )} -> 0 | F11: {=IFERROR( SMALL( IF( ( (TRIM(UPPER(CUT_LIST!$F$6:$F$1000))="NO") + (TRIM(UPPER(CUT_LIST!$F$6:$F$1000))="YES")* (N(CUT_LIST!$D$6:$D$1000)-MIN(N(CUT_LIST!$D$6:$D$1000),N(CUT_LIST!$G$6:$G$1000))>0) )>0, ROW(CUT_LIST!$F$6:$F$1000)-ROW(CUT_LIST!$F$6)+1 ), ROWS($F$7:F11) ), "")} -> 5
A12: {=IF($F12="","",INDEX(CUT_LIST!$A$6:$A$1000,$F12))} -> 0 | B12: {=IF($F12="","",INDEX(CUT_LIST!$B$6:$B$1000,$F12))} -> 0 | C12: {=IF($F12="","",INDEX(CUT_LIST!$C$6:$C$1000,$F12))} -> 0 | D12: {=IF($F12="","", IF( TRIM(UPPER(INDEX(CUT_LIST!$F$6:$F$1000,$F12)))="NO", N(INDEX(CUT_LIST!$D$6:$D$1000,$F12)), N(INDEX(CUT_LIST!$D$6:$D$1000,$F12))- MIN( N(INDEX(CUT_LIST!$D$6:$D$1000,$F12)), N(INDEX(CUT_LIST!$G$6:$G$1000,$F12)) ) ) )} -> 0 | F12: {=IFERROR( SMALL( IF( ( (TRIM(UPPER(CUT_LIST!$F$6:$F$1000))="NO") + (TRIM(UPPER(CUT_LIST!$F$6:$F$1000))="YES")* (N(CUT_LIST!$D$6:$D$1000)-MIN(N(CUT_LIST!$D$6:$D$1000),N(CUT_LIST!$G$6:$G$1000))>0) )>0, ROW(CUT_LIST!$F$6:$F$1000)-ROW(CUT_LIST!$F$6)+1 ), ROWS($F$7:F12) ), "")} -> 6
A13: {=IF($F13="","",INDEX(CUT_LIST!$A$6:$A$1000,$F13))} -> 0 | B13: {=IF($F13="","",INDEX(CUT_LIST!$B$6:$B$1000,$F13))} -> 0 | C13: {=IF($F13="","",INDEX(CUT_LIST!$C$6:$C$1000,$F13))} -> 0 | D13: {=IF($F13="","", IF( TRIM(UPPER(INDEX(CUT_LIST!$F$6:$F$1000,$F13)))="NO", N(INDEX(CUT_LIST!$D$6:$D$1000,$F13)), N(INDEX(CUT_LIST!$D$6:$D$1000,$F13))- MIN( N(INDEX(CUT_LIST!$D$6:$D$1000,$F13)), N(INDEX(CUT_LIST!$G$6:$G$1000,$F13)) ) ) )} -> 0 | F13: {=IFERROR( SMALL( IF( ( (TRIM(UPPER(CUT_LIST!$F$6:$F$1000))="NO") + (TRIM(UPPER(CUT_LIST!$F$6:$F$1000))="YES")* (N(CUT_LIST!$D$6:$D$1000)-MIN(N(CUT_LIST!$D$6:$D$1000),N(CUT_LIST!$G$6:$G$1000))>0) )>0, ROW(CUT_LIST!$F$6:$F$1000)-ROW(CUT_LIST!$F$6)+1 ), ROWS($F$7:F13) ), "")} -> 7
A14: {=IF($F14="","",INDEX(CUT_LIST!$A$6:$A$1000,$F14))} -> 0 | B14: {=IF($F14="","",INDEX(CUT_LIST!$B$6:$B$1000,$F14))} -> 0 | C14: {=IF($F14="","",INDEX(CUT_LIST!$C$6:$C$1000,$F14))} -> 0 | D14: {=IF($F14="","", IF( TRIM(UPPER(INDEX(CUT_LIST!$F$6:$F$1000,$F14)))="NO", N(INDEX(CUT_LIST!$D$6:$D$1000,$F14)), N(INDEX(CUT_LIST!$D$6:$D$1000,$F14))- MIN( N(INDEX(CUT_LIST!$D$6:$D$1000,$F14)), N(INDEX(CUT_LIST!$G$6:$G$1000,$F14)) ) ) )} -> 0 | F14: {=IFERROR( SMALL( IF( ( (TRIM(UPPER(CUT_LIST!$F$6:$F$1000))="NO") + (TRIM(UPPER(CUT_LIST!$F$6:$F$1000))="YES")* (N(CUT_LIST!$D$6:$D$1000)-MIN(N(CUT_LIST!$D$6:$D$1000),N(CUT_LIST!$G$6:$G$1000))>0) )>0, ROW(CUT_LIST!$F$6:$F$1000)-ROW(CUT_LIST!$F$6)+1 ), ROWS($F$7:F14) ), "")} -> 8
A15: {=IF($F15="","",INDEX(CUT_LIST!$A$6:$A$1000,$F15))} -> 0 | B15: {=IF($F15="","",INDEX(CUT_LIST!$B$6:$B$1000,$F15))} -> 0 | C15: {=IF($F15="","",INDEX(CUT_LIST!$C$6:$C$1000,$F15))} -> 0 | D15: {=IF($F15="","", IF( TRIM(UPPER(INDEX(CUT_LIST!$F$6:$F$1000,$F15)))="NO", N(INDEX(CUT_LIST!$D$6:$D$1000,$F15)), N(INDEX(CUT_LIST!$D$6:$D$1000,$F15))- MIN( N(INDEX(CUT_LIST!$D$6:$D$1000,$F15)), N(INDEX(CUT_LIST!$G$6:$G$1000,$F15)) ) ) )} -> 0 | F15: {=IFERROR( SMALL( IF( ( (TRIM(UPPER(CUT_LIST!$F$6:$F$1000))="NO") + (TRIM(UPPER(CUT_LIST!$F$6:$F$1000))="YES")* (N(CUT_LIST!$D$6:$D$1000)-MIN(N(CUT_LIST!$D$6:$D$1000),N(CUT_LIST!$G$6:$G$1000))>0) )>0, ROW(CUT_LIST!$F$6:$F$1000)-ROW(CUT_LIST!$F$6)+1 ), ROWS($F$7:F15) ), "")} -> 9
A16: {=IF($F16="","",INDEX(CUT_LIST!$A$6:$A$1000,$F16))} -> 0 | B16: {=IF($F16="","",INDEX(CUT_LIST!$B$6:$B$1000,$F16))} -> 0 | C16: {=IF($F16="","",INDEX(CUT_LIST!$C$6:$C$1000,$F16))} -> 0 | D16: {=IF($F16="","", IF( TRIM(UPPER(INDEX(CUT_LIST!$F$6:$F$1000,$F16)))="NO", N(INDEX(CUT_LIST!$D$6:$D$1000,$F16)), N(INDEX(CUT_LIST!$D$6:$D$1000,$F16))- MIN( N(INDEX(CUT_LIST!$D$6:$D$1000,$F16)), N(INDEX(CUT_LIST!$G$6:$G$1000,$F16)) ) ) )} -> 0 | F16: {=IFERROR( SMALL( IF( ( (TRIM(UPPER(CUT_LIST!$F$6:$F$1000))="NO") + (TRIM(UPPER(CUT_LIST!$F$6:$F$1000))="YES")* (N(CUT_LIST!$D$6:$D$1000)-MIN(N(CUT_LIST!$D$6:$D$1000),N(CUT_LIST!$G$6:$G$1000))>0) )>0, ROW(CUT_LIST!$F$6:$F$1000)-ROW(CUT_LIST!$F$6)+1 ), ROWS($F$7:F16) ), "")} -> 10
A17: {=IF($F17="","",INDEX(CUT_LIST!$A$6:$A$1000,$F17))} -> 0 | B17: {=IF($F17="","",INDEX(CUT_LIST!$B$6:$B$1000,$F17))} -> 0 | C17: {=IF($F17="","",INDEX(CUT_LIST!$C$6:$C$1000,$F17))} -> 0 | D17: {=IF($F17="","", IF( TRIM(UPPER(INDEX(CUT_LIST!$F$6:$F$1000,$F17)))="NO", N(INDEX(CUT_LIST!$D$6:$D$1000,$F17)), N(INDEX(CUT_LIST!$D$6:$D$1000,$F17))- MIN( N(INDEX(CUT_LIST!$D$6:$D$1000,$F17)), N(INDEX(CUT_LIST!$G$6:$G$1000,$F17)) ) ) )} -> 0 | F17: {=IFERROR( SMALL( IF( ( (TRIM(UPPER(CUT_LIST!$F$6:$F$1000))="NO") + (TRIM(UPPER(CUT_LIST!$F$6:$F$1000))="YES")* (N(CUT_LIST!$D$6:$D$1000)-MIN(N(CUT_LIST!$D$6:$D$1000),N(CUT_LIST!$G$6:$G$1000))>0) )>0, ROW(CUT_LIST!$F$6:$F$1000)-ROW(CUT_LIST!$F$6)+1 ), ROWS($F$7:F17) ), "")} -> 11
A18: {=IF($F18="","",INDEX(CUT_LIST!$A$6:$A$1000,$F18))} -> 0 | B18: {=IF($F18="","",INDEX(CUT_LIST!$B$6:$B$1000,$F18))} -> 0 | C18: {=IF($F18="","",INDEX(CUT_LIST!$C$6:$C$1000,$F18))} -> 0 | D18: {=IF($F18="","", IF( TRIM(UPPER(INDEX(CUT_LIST!$F$6:$F$1000,$F18)))="NO", N(INDEX(CUT_LIST!$D$6:$D$1000,$F18)), N(INDEX(CUT_LIST!$D$6:$D$1000,$F18))- MIN( N(INDEX(CUT_LIST!$D$6:$D$1000,$F18)), N(INDEX(CUT_LIST!$G$6:$G$1000,$F18)) ) ) )} -> 0 | F18: {=IFERROR( SMALL( IF( ( (TRIM(UPPER(CUT_LIST!$F$6:$F$1000))="NO") + (TRIM(UPPER(CUT_LIST!$F$6:$F$1000))="YES")* (N(CUT_LIST!$D$6:$D$1000)-MIN(N(CUT_LIST!$D$6:$D$1000),N(CUT_LIST!$G$6:$G$1000))>0) )>0, ROW(CUT_LIST!$F$6:$F$1000)-ROW(CUT_LIST!$F$6)+1 ), ROWS($F$7:F18) ), "")} -> 12
... A1045: {=IF($F1045="","",INDEX(CUT_LIST!$A$6:$A$1000,$F1045))} | B1045: {=IF($F1045="","",INDEX(CUT_LIST!$B$6:$B$1000,$F1045))} | C1045: {=IF($F1045="","",INDEX(CUT_LIST!$C$6:$C$1000,$F1045))} | D1045: {=IF($F1045="","", IF( TRIM(UPPER(INDEX(CUT_LIST!$F$6:$F$1000,$F1045)))="NO", N(INDEX(CUT_LIST!$D$6:$D$1000,$F1045)), N(INDEX(CUT_LIST!$D$6:$D$1000,$F1045))- MIN( N(INDEX(CUT_LIST!$D$6:$D$1000,$F1045)), N(INDEX(CUT_LIST!$G$6:$G$1000,$F1045)) ) ) )} | F1045: {=IFERROR( SMALL( IF( ( (TRIM(UPPER(CUT_LIST!$F$6:$F$1000))="NO") + (TRIM(UPPER(CUT_LIST!$F$6:$F$1000))="YES")* (N(CUT_LIST!$D$6:$D$1000)-MIN(N(CUT_LIST!$D$6:$D$1000),N(CUT_LIST!$G$6:$G$1000))>0) )>0, ROW(CUT_LIST!$F$6:$F$1000)-ROW(CUT_LIST!$F$6)+1 ), ROWS($F$7:F1045) ), "")}
A1046: {=IF($F1046="","",INDEX(CUT_LIST!$A$2:$A$1000,$F1046))} | B1046: {=IF($F1046="","",INDEX(CUT_LIST!$B$2:$B$1000,$F1046))} | C1046: {=IF($F1046="","",INDEX(CUT_LIST!$C$2:$C$1000,$F1046))} | D1046: {=IF($F1046="","",INDEX(CUT_LIST!$D$2:$D$1000,$F1046))} | F1046: {=IFERROR(SMALL(IF(CUT_LIST!$F$2:$F$1000="NO",ROW(CUT_LIST!$F$2:$F$1000)-ROW(CUT_LIST!$F$2)+1),ROWS($F$7:F1046)),"")}
A1047: {=IF($F1047="","",INDEX(CUT_LIST!$A$2:$A$1000,$F1047))} | B1047: {=IF($F1047="","",INDEX(CUT_LIST!$B$2:$B$1000,$F1047))} | C1047: {=IF($F1047="","",INDEX(CUT_LIST!$C$2:$C$1000,$F1047))} | D1047: {=IF($F1047="","",INDEX(CUT_LIST!$D$2:$D$1000,$F1047))} | F1047: {=IFERROR(SMALL(IF(CUT_LIST!$F$2:$F$1000="NO",ROW(CUT_LIST!$F$2:$F$1000)-ROW(CUT_LIST!$F$2)+1),ROWS($F$7:F1047)),"")}
A1048: {=IF($F1048="","",INDEX(CUT_LIST!$A$2:$A$1000,$F1048))} | B1048: {=IF($F1048="","",INDEX(CUT_LIST!$B$2:$B$1000,$F1048))} | C1048: {=IF($F1048="","",INDEX(CUT_LIST!$C$2:$C$1000,$F1048))} | D1048: {=IF($F1048="","",INDEX(CUT_LIST!$D$2:$D$1000,$F1048))} | F1048: {=IFERROR(SMALL(IF(CUT_LIST!$F$2:$F$1000="NO",ROW(CUT_LIST!$F$2:$F$1000)-ROW(CUT_LIST!$F$2)+1),ROWS($F$7:F1048)),"")}
A1049: {=IF($F1049="","",INDEX(CUT_LIST!$A$2:$A$1000,$F1049))} | B1049: {=IF($F1049="","",INDEX(CUT_LIST!$B$2:$B$1000,$F1049))} | C1049: {=IF($F1049="","",INDEX(CUT_LIST!$C$2:$C$1000,$F1049))} | D1049: {=IF($F1049="","",INDEX(CUT_LIST!$D$2:$D$1000,$F1049))} | F1049: {=IFERROR(SMALL(IF(CUT_LIST!$F$2:$F$1000="NO",ROW(CUT_LIST!$F$2:$F$1000)-ROW(CUT_LIST!$F$2)+1),ROWS($F$7:F1049)),"")}
A1050: {=IF($F1050="","",INDEX(CUT_LIST!$A$2:$A$1000,$F1050))} | B1050: {=IF($F1050="","",INDEX(CUT_LIST!$B$2:$B$1000,$F1050))} | C1050: {=IF($F1050="","",INDEX(CUT_LIST!$C$2:$C$1000,$F1050))} | D1050: {=IF($F1050="","",INDEX(CUT_LIST!$D$2:$D$1000,$F1050))} | F1050: {=IFERROR(SMALL(IF(CUT_LIST!$F$2:$F$1000="NO",ROW(CUT_LIST!$F$2:$F$1000)-ROW(CUT_LIST!$F$2)+1),ROWS($F$7:F1050)),"")}
A1051: {=IF($F1051="","",INDEX(CUT_LIST!$A$2:$A$1000,$F1051))} | B1051: {=IF($F1051="","",INDEX(CUT_LIST!$B$2:$B$1000,$F1051))} | C1051: {=IF($F1051="","",INDEX(CUT_LIST!$C$2:$C$1000,$F1051))} | D1051: {=IF($F1051="","",INDEX(CUT_LIST!$D$2:$D$1000,$F1051))} | F1051: {=IFERROR(SMALL(IF(CUT_LIST!$F$2:$F$1000="NO",ROW(CUT_LIST!$F$2:$F$1000)-ROW(CUT_LIST!$F$2)+1),ROWS($F$7:F1051)),"")}
A1052: {=IF($F1052="","",INDEX(CUT_LIST!$A$2:$A$1000,$F1052))} | B1052: {=IF($F1052="","",INDEX(CUT_LIST!$B$2:$B$1000,$F1052))} | C1052: {=IF($F1052="","",INDEX(CUT_LIST!$C$2:$C$1000,$F1052))} | D1052: {=IF($F1052="","",INDEX(CUT_LIST!$D$2:$D$1000,$F1052))} | F1052: {=IFERROR(SMALL(IF(CUT_LIST!$F$2:$F$1000="NO",ROW(CUT_LIST!$F$2:$F$1000)-ROW(CUT_LIST!$F$2)+1),ROWS($F$7:F1052)),"")}
A1053: {=IF($F1053="","",INDEX(CUT_LIST!$A$2:$A$1000,$F1053))} | B1053: {=IF($F1053="","",INDEX(CUT_LIST!$B$2:$B$1000,$F1053))} | C1053: {=IF($F1053="","",INDEX(CUT_LIST!$C$2:$C$1000,$F1053))} | D1053: {=IF($F1053="","",INDEX(CUT_LIST!$D$2:$D$1000,$F1053))} | F1053: {=IFERROR(SMALL(IF(CUT_LIST!$F$2:$F$1000="NO",ROW(CUT_LIST!$F$2:$F$1000)-ROW(CUT_LIST!$F$2)+1),ROWS($F$7:F1053)),"")}
A1054: {=IF($F1054="","",INDEX(CUT_LIST!$A$2:$A$1000,$F1054))} | B1054: {=IF($F1054="","",INDEX(CUT_LIST!$B$2:$B$1000,$F1054))} | C1054: {=IF($F1054="","",INDEX(CUT_LIST!$C$2:$C$1000,$F1054))} | D1054: {=IF($F1054="","",INDEX(CUT_LIST!$D$2:$D$1000,$F1054))} | F1054: {=IFERROR(SMALL(IF(CUT_LIST!$F$2:$F$1000="NO",ROW(CUT_LIST!$F$2:$F$1000)-ROW(CUT_LIST!$F$2)+1),ROWS($F$7:F1054)),"")}
A1055: {=IF($F1055="","",INDEX(CUT_LIST!$A$2:$A$1000,$F1055))} | B1055: {=IF($F1055="","",INDEX(CUT_LIST!$B$2:$B$1000,$F1055))} | C1055: {=IF($F1055="","",INDEX(CUT_LIST!$C$2:$C$1000,$F1055))} | D1055: {=IF($F1055="","",INDEX(CUT_LIST!$D$2:$D$1000,$F1055))} | F1055: {=IFERROR(SMALL(IF(CUT_LIST!$F$2:$F$1000="NO",ROW(CUT_LIST!$F$2:$F$1000)-ROW(CUT_LIST!$F$2)+1),ROWS($F$7:F1055)),"")}
A1056: {=IF($F1056="","",INDEX(CUT_LIST!$A$2:$A$1000,$F1056))} | B1056: {=IF($F1056="","",INDEX(CUT_LIST!$B$2:$B$1000,$F1056))} | C1056: {=IF($F1056="","",INDEX(CUT_LIST!$C$2:$C$1000,$F1056))} | D1056: {=IF($F1056="","",INDEX(CUT_LIST!$D$2:$D$1000,$F1056))} | F1056: {=IFERROR(SMALL(IF(CUT_LIST!$F$2:$F$1000="NO",ROW(CUT_LIST!$F$2:$F$1000)-ROW(CUT_LIST!$F$2)+1),ROWS($F$7:F1056)),"")}
A1057: {=IF($F1057="","",INDEX(CUT_LIST!$A$2:$A$1000,$F1057))} | B1057: {=IF($F1057="","",INDEX(CUT_LIST!$B$2:$B$1000,$F1057))} | C1057: {=IF($F1057="","",INDEX(CUT_LIST!$C$2:$C$1000,$F1057))} | D1057: {=IF($F1057="","",INDEX(CUT_LIST!$D$2:$D$1000,$F1057))} | F1057: {=IFERROR(SMALL(IF(CUT_LIST!$F$2:$F$1000="NO",ROW(CUT_LIST!$F$2:$F$1000)-ROW(CUT_LIST!$F$2)+1),ROWS($F$7:F1057)),"")}
... A1068: {=IF($F1068="","",INDEX(CUT_LIST!$A$2:$A$1000,$F1068))} | B1068: {=IF($F1068="","",INDEX(CUT_LIST!$B$2:$B$1000,$F1068))} | C1068: {=IF($F1068="","",INDEX(CUT_LIST!$C$2:$C$1000,$F1068))} | D1068: {=IF($F1068="","",INDEX(CUT_LIST!$D$2:$D$1000,$F1068))} | F1068: {=IFERROR(SMALL(IF(CUT_LIST!$F$2:$F$1000="NO",ROW(CUT_LIST!$F$2:$F$1000)-ROW(CUT_LIST!$F$2)+1),ROWS($F$7:F1068)),"")}
B1069: {=IF($F1069="","",INDEX(CUT_LIST!$B$2:$B$1000,$F1069))} | C1069: {=IF($F1069="","",INDEX(CUT_LIST!$C$2:$C$1000,$F1069))} | D1069: {=IF($F1069="","",INDEX(CUT_LIST!$D$2:$D$1000,$F1069))} | F1069: {=IFERROR(SMALL(IF(CUT_LIST!$F$2:$F$1000="NO",ROW(CUT_LIST!$F$2:$F$1000)-ROW(CUT_LIST!$F$2)+1),ROWS($F$7:F1069)),"")}
B1070: {=IF($F1070="","",INDEX(CUT_LIST!$B$2:$B$1000,$F1070))} | C1070: {=IF($F1070="","",INDEX(CUT_LIST!$C$2:$C$1000,$F1070))} | D1070: {=IF($F1070="","",INDEX(CUT_LIST!$D$2:$D$1000,$F1070))} | F1070: {=IFERROR(SMALL(IF(CUT_LIST!$F$2:$F$1000="NO",ROW(CUT_LIST!$F$2:$F$1000)-ROW(CUT_LIST!$F$2)+1),ROWS($F$7:F1070)),"")}
B1071: {=IF($F1071="","",INDEX(CUT_LIST!$B$2:$B$1000,$F1071))} | C1071: {=IF($F1071="","",INDEX(CUT_LIST!$C$2:$C$1000,$F1071))} | D1071: {=IF($F1071="","",INDEX(CUT_LIST!$D$2:$D$1000,$F1071))} | F1071: {=IFERROR(SMALL(IF(CUT_LIST!$F$2:$F$1000="NO",ROW(CUT_LIST!$F$2:$F$1000)-ROW(CUT_LIST!$F$2)+1),ROWS($F$7:F1071)),"")}
B1072: {=IF($F1072="","",INDEX(CUT_LIST!$B$2:$B$1000,$F1072))} | C1072: {=IF($F1072="","",INDEX(CUT_LIST!$C$2:$C$1000,$F1072))} | D1072: {=IF($F1072="","",INDEX(CUT_LIST!$D$2:$D$1000,$F1072))} | F1072: {=IFERROR(SMALL(IF(CUT_LIST!$F$2:$F$1000="NO",ROW(CUT_LIST!$F$2:$F$1000)-ROW(CUT_LIST!$F$2)+1),ROWS($F$7:F1072)),"")}
B1073: {=IF($F1073="","",INDEX(CUT_LIST!$B$2:$B$1000,$F1073))} | C1073: {=IF($F1073="","",INDEX(CUT_LIST!$C$2:$C$1000,$F1073))} | D1073: {=IF($F1073="","",INDEX(CUT_LIST!$D$2:$D$1000,$F1073))} | F1073: {=IFERROR(SMALL(IF(CUT_LIST!$F$2:$F$1000="NO",ROW(CUT_LIST!$F$2:$F$1000)-ROW(CUT_LIST!$F$2)+1),ROWS($F$7:F1073)),"")}
B1074: {=IF($F1074="","",INDEX(CUT_LIST!$B$2:$B$1000,$F1074))} | C1074: {=IF($F1074="","",INDEX(CUT_LIST!$C$2:$C$1000,$F1074))} | D1074: {=IF($F1074="","",INDEX(CUT_LIST!$D$2:$D$1000,$F1074))} | F1074: {=IFERROR(SMALL(IF(CUT_LIST!$F$2:$F$1000="NO",ROW(CUT_LIST!$F$2:$F$1000)-ROW(CUT_LIST!$F$2)+1),ROWS($F$7:F1074)),"")}
B1075: {=IF($F1075="","",INDEX(CUT_LIST!$B$2:$B$1000,$F1075))} | C1075: {=IF($F1075="","",INDEX(CUT_LIST!$C$2:$C$1000,$F1075))} | D1075: {=IF($F1075="","",INDEX(CUT_LIST!$D$2:$D$1000,$F1075))} | F1075: {=IFERROR(SMALL(IF(CUT_LIST!$F$2:$F$1000="NO",ROW(CUT_LIST!$F$2:$F$1000)-ROW(CUT_LIST!$F$2)+1),ROWS($F$7:F1075)),"")}
B1076: {=IF($F1076="","",INDEX(CUT_LIST!$B$2:$B$1000,$F1076))} | C1076: {=IF($F1076="","",INDEX(CUT_LIST!$C$2:$C$1000,$F1076))} | D1076: {=IF($F1076="","",INDEX(CUT_LIST!$D$2:$D$1000,$F1076))} | F1076: {=IFERROR(SMALL(IF(CUT_LIST!$F$2:$F$1000="NO",ROW(CUT_LIST!$F$2:$F$1000)-ROW(CUT_LIST!$F$2)+1),ROWS($F$7:F1076)),"")}
B1077: {=IF($F1077="","",INDEX(CUT_LIST!$B$2:$B$1000,$F1077))} | C1077: {=IF($F1077="","",INDEX(CUT_LIST!$C$2:$C$1000,$F1077))} | D1077: {=IF($F1077="","",INDEX(CUT_LIST!$D$2:$D$1000,$F1077))} | F1077: {=IFERROR(SMALL(IF(CUT_LIST!$F$2:$F$1000="NO",ROW(CUT_LIST!$F$2:$F$1000)-ROW(CUT_LIST!$F$2)+1),ROWS($F$7:F1077)),"")}
...

Sheet PROFILE COST
A1: PROJECT NAME: | B1: =CUT_LIST!B1 -> 0
A2: DATE: | B2: =CUT_LIST!B2 -> 0
A4: POFILE CODE | B4: PROFILE WEIGHT | C4: TOTAL LENGTHS REQUIRED | D4: LENGTH SIZE (MM) | E4: TOTAL WEIGHT | F4: COST PER KG | G4: TOTAL COST | J4: COST PER KG
A5: =SUMMARY!A6 | B5: =IFERROR(INDEX('WEIGHT CATALOGUE'!D:D, MATCH(A5,'WEIGHT CATALOGUE'!B:B, 0)), "Not Found") -> Not Found | C5: =IFERROR(INDEX(SUMMARY!C:C, MATCH(A5, SUMMARY!A:A, 0)), 0) -> 0 | D5: =SUMMARY!$G$6 -> 6400 | E5: =B5*C5*(D5/1000) -> #VALUE! | F5: =$J$5 -> 675 | G5: =E5*F5 -> #VALUE! | J5: 675
A6: =SUMMARY!A7 | B6: =IFERROR(INDEX('WEIGHT CATALOGUE'!D:D, MATCH(A6,'WEIGHT CATALOGUE'!B:B, 0)), "Not Found") -> Not Found | C6: =IFERROR(INDEX(SUMMARY!C:C, MATCH(A6, SUMMARY!A:A, 0)), 0) -> 0 | D6: =SUMMARY!$G$6 -> 6400 | E6: =B6*C6*(D6/1000) -> #VALUE! | F6: =$J$5 -> 675 | G6: =E6*F6 -> #VALUE!
A7: =SUMMARY!A8 | B7: =IFERROR(INDEX('WEIGHT CATALOGUE'!D:D, MATCH(A7,'WEIGHT CATALOGUE'!B:B, 0)), "Not Found") -> Not Found | C7: =IFERROR(INDEX(SUMMARY!C:C, MATCH(A7, SUMMARY!A:A, 0)), 0) -> 0 | D7: =SUMMARY!$G$6 -> 6400 | E7: =B7*C7*(D7/1000) -> #VALUE! | F7: =$J$5 -> 675 | G7: =E7*F7 -> #VALUE!
A8: =SUMMARY!A9 | B8: =IFERROR(INDEX('WEIGHT CATALOGUE'!D:D, MATCH(A8,'WEIGHT CATALOGUE'!B:B, 0)), "Not Found") -> Not Found | C8: =IFERROR(INDEX(SUMMARY!C:C, MATCH(A8, SUMMARY!A:A, 0)), 0) -> 0 | D8: =SUMMARY!$G$6 -> 6400 | E8: =B8*C8*(D8/1000) -> #VALUE! | F8: =$J$5 -> 675 | G8: =E8*F8 -> #VALUE!
A9: =SUMMARY!A10 | B9: =IFERROR(INDEX('WEIGHT CATALOGUE'!D:D, MATCH(A9,'WEIGHT CATALOGUE'!B:B, 0)), "Not Found") -> Not Found | C9: =IFERROR(INDEX(SUMMARY!C:C, MATCH(A9, SUMMARY!A:A, 0)), 0) -> 0 | D9: =SUMMARY!$G$6 -> 6400 | E9: =B9*C9*(D9/1000) -> #VALUE! | F9: =$J$5 -> 675 | G9: =E9*F9 -> #VALUE!
A10: =SUMMARY!A11 | B10: =IFERROR(INDEX('WEIGHT CATALOGUE'!D:D, MATCH(A10,'WEIGHT CATALOGUE'!B:B, 0)), "Not Found") -> Not Found | C10: =IFERROR(INDEX(SUMMARY!C:C, MATCH(A10, SUMMARY!A:A, 0)), 0) -> 0 | D10: =SUMMARY!$G$6 -> 6400 | E10: =B10*C10*(D10/1000) -> #VALUE! | F10: =$J$5 -> 675 | G10: =E10*F10 -> #VALUE!
A11: =SUMMARY!A12 | B11: =IFERROR(INDEX('WEIGHT CATALOGUE'!D:D, MATCH(A11,'WEIGHT CATALOGUE'!B:B, 0)), "Not Found") -> Not Found | C11: =IFERROR(INDEX(SUMMARY!C:C, MATCH(A11, SUMMARY!A:A, 0)), 0) -> 0 | D11: =SUMMARY!$G$6 -> 6400 | E11: =B11*C11*(D11/1000) -> #VALUE! | F11: =$J$5 -> 675 | G11: =E11*F11 -> #VALUE!
A12: =SUMMARY!A13 | B12: =IFERROR(INDEX('WEIGHT CATALOGUE'!D:D, MATCH(A12,'WEIGHT CATALOGUE'!B:B, 0)), "Not Found") -> Not Found | C12: =IFERROR(INDEX(SUMMARY!C:C, MATCH(A12, SUMMARY!A:A, 0)), 0) -> 0 | D12: =SUMMARY!$G$6 -> 6400 | E12: =B12*C12*(D12/1000) -> #VALUE! | F12: =$J$5 -> 675 | G12: =E12*F12 -> #VALUE!
A13: =SUMMARY!A14 | B13: =IFERROR(INDEX('WEIGHT CATALOGUE'!D:D, MATCH(A13,'WEIGHT CATALOGUE'!B:B, 0)), "Not Found") -> Not Found | C13: =IFERROR(INDEX(SUMMARY!C:C, MATCH(A13, SUMMARY!A:A, 0)), 0) -> 0 | D13: =SUMMARY!$G$6 -> 6400 | E13: =B13*C13*(D13/1000) -> #VALUE! | F13: =$J$5 -> 675 | G13: =E13*F13 -> #VALUE!
A14: =SUMMARY!A15 | B14: =IFERROR(INDEX('WEIGHT CATALOGUE'!D:D, MATCH(A14,'WEIGHT CATALOGUE'!B:B, 0)), "Not Found") -> Not Found | C14: =IFERROR(INDEX(SUMMARY!C:C, MATCH(A14, SUMMARY!A:A, 0)), 0) -> 0 | D14: =SUMMARY!$G$6 -> 6400 | E14: =B14*C14*(D14/1000) -> #VALUE! | F14: =$J$5 -> 675 | G14: =E14*F14 -> #VALUE!
A15: =SUMMARY!A16 | B15: =IFERROR(INDEX('WEIGHT CATALOGUE'!D:D, MATCH(A15,'WEIGHT CATALOGUE'!B:B, 0)), "Not Found") -> Not Found | C15: =IFERROR(INDEX(SUMMARY!C:C, MATCH(A15, SUMMARY!A:A, 0)), 0) -> 0 | D15: =SUMMARY!$G$6 -> 6400 | E15: =B15*C15*(D15/1000) -> #VALUE! | F15: =$J$5 -> 675 | G15: =E15*F15 -> #VALUE!
A16: =SUMMARY!A17 | B16: =IFERROR(INDEX('WEIGHT CATALOGUE'!D:D, MATCH(A16,'WEIGHT CATALOGUE'!B:B, 0)), "Not Found") -> Not Found | C16: =IFERROR(INDEX(SUMMARY!C:C, MATCH(A16, SUMMARY!A:A, 0)), 0) -> 0 | D16: =SUMMARY!$G$6 -> 6400 | E16: =B16*C16*(D16/1000) -> #VALUE! | F16: =$J$5 -> 675 | G16: =E16*F16 -> #VALUE!
A17: =SUMMARY!A18 | B17: =IFERROR(INDEX('WEIGHT CATALOGUE'!D:D, MATCH(A17,'WEIGHT CATALOGUE'!B:B, 0)), "Not Found") -> Not Found | C17: =IFERROR(INDEX(SUMMARY!C:C, MATCH(A17, SUMMARY!A:A, 0)), 0) -> 0 | D17: =SUMMARY!$G$6 -> 6400 | E17: =B17*C17*(D17/1000) -> #VALUE! | F17: =$J$5 -> 675 | G17: =E17*F17 -> #VALUE!
... A24: =SUMMARY!A25 | B24: =IFERROR(INDEX('WEIGHT CATALOGUE'!D:D, MATCH(A24,'WEIGHT CATALOGUE'!B:B, 0)), "Not Found") -> Not Found | C24: =IFERROR(INDEX(SUMMARY!C:C, MATCH(A24, SUMMARY!A:A, 0)), 0) -> 0 | D24: =SUMMARY!$G$6 -> 6400 | E24: =B24*C24*(D24/1000) -> #VALUE! | F24: =$J$5 -> 675 | G24: =E24*F24 -> #VALUE!
A25: MANUAL CALCULATION
A26: =SUMMARY!A28 -> 0 | B26: =IFERROR(INDEX('WEIGHT CATALOGUE'!D:D, MATCH(A26,'WEIGHT CATALOGUE'!B:B, 0)), "Not Found") -> Not Found | C26: =SUMMARY!C28 -> 0 | D26: =SUMMARY!B28 -> 6400 | E26: =B26*C26*(D26/1000) -> #VALUE! | F26: =$J$5 -> 675 | G26: =E26*F26 -> #VALUE!
A27: =SUMMARY!A29 -> 0 | B27: =IFERROR(INDEX('WEIGHT CATALOGUE'!D:D, MATCH(A27,'WEIGHT CATALOGUE'!B:B, 0)), "Not Found") -> Not Found | C27: =SUMMARY!C29 -> 0 | D27: =SUMMARY!$G$6 -> 6400 | E27: =B27*C27*(D27/1000) -> #VALUE! | F27: =$J$5 -> 675 | G27: =E27*F27 -> #VALUE!
A28: =SUMMARY!A30 -> 0 | B28: =IFERROR(INDEX('WEIGHT CATALOGUE'!D:D, MATCH(A28,'WEIGHT CATALOGUE'!B:B, 0)), "Not Found") -> Not Found | C28: =SUMMARY!C30 -> 0 | D28: =SUMMARY!$G$6 -> 6400 | E28: =B28*C28*(D28/1000) -> #VALUE! | F28: =$J$5 -> 675 | G28: =E28*F28 -> #VALUE!
A29: =SUMMARY!A31 -> 0 | B29: =IFERROR(INDEX('WEIGHT CATALOGUE'!D:D, MATCH(A29,'WEIGHT CATALOGUE'!B:B, 0)), "Not Found") -> Not Found | C29: =SUMMARY!C31 -> 0 | D29: =SUMMARY!$G$6 -> 6400 | E29: =B29*C29*(D29/1000) -> #VALUE! | F29: =$J$5 -> 675 | G29: =E29*F29 -> #VALUE!
A30: =SUMMARY!A32 -> 0 | B30: =IFERROR(INDEX('WEIGHT CATALOGUE'!D:D, MATCH(A30,'WEIGHT CATALOGUE'!B:B, 0)), "Not Found") -> Not Found | C30: =SUMMARY!C32 -> 0 | D30: =SUMMARY!$G$6 -> 6400 | E30: =B30*C30*(D30/1000) -> #VALUE! | F30: =$J$5 -> 675 | G30: =E30*F30 -> #VALUE!
A31: =SUMMARY!A33 -> 0 | B31: =IFERROR(INDEX('WEIGHT CATALOGUE'!D:D, MATCH(A31,'WEIGHT CATALOGUE'!B:B, 0)), "Not Found") -> Not Found | C31: =SUMMARY!C33 -> 0 | D31: =SUMMARY!$G$6 -> 6400 | E31: =B31*C31*(D31/1000) -> #VALUE! | F31: =$J$5 -> 675 | G31: =E31*F31 -> #VALUE!
A32: =SUMMARY!A34 -> 0 | B32: =IFERROR(INDEX('WEIGHT CATALOGUE'!D:D, MATCH(A32,'WEIGHT CATALOGUE'!B:B, 0)), "Not Found") -> Not Found | C32: =SUMMARY!C34 -> 0 | D32: =SUMMARY!$G$6 -> 6400 | E32: =B32*C32*(D32/1000) -> #VALUE! | F32: =$J$5 -> 675 | G32: =E32*F32 -> #VALUE!
A33: =SUMMARY!A35 -> 0 | B33: =IFERROR(INDEX('WEIGHT CATALOGUE'!D:D, MATCH(A33,'WEIGHT CATALOGUE'!B:B, 0)), "Not Found") -> Not Found | C33: =SUMMARY!C35 -> 0 | D33: =SUMMARY!$G$6 -> 6400 | E33: =B33*C33*(D33/1000) -> #VALUE! | F33: =$J$5 -> 675 | G33: =E33*F33 -> #VALUE!
A34: =SUMMARY!A36 -> 0 | B34: =IFERROR(INDEX('WEIGHT CATALOGUE'!D:D, MATCH(A34,'WEIGHT CATALOGUE'!B:B, 0)), "Not Found") -> Not Found | C34: =SUMMARY!C36 -> 0 | D34: =SUMMARY!$G$6 -> 6400 | E34: =B34*C34*(D34/1000) -> #VALUE! | F34: =$J$5 -> 675 | G34: =E34*F34 -> #VALUE!
A35: =SUMMARY!A37 -> 0 | B35: =IFERROR(INDEX('WEIGHT CATALOGUE'!D:D, MATCH(A35,'WEIGHT CATALOGUE'!B:B, 0)), "Not Found") -> Not Found | C35: =SUMMARY!C37 -> 0 | D35: =SUMMARY!$G$6 -> 6400 | E35: =B35*C35*(D35/1000) -> #VALUE! | F35: =$J$5 -> 675 | G35: =E35*F35 -> #VALUE!
A36: =SUMMARY!A38 -> 0 | B36: =IFERROR(INDEX('WEIGHT CATALOGUE'!D:D, MATCH(A36,'WEIGHT CATALOGUE'!B:B, 0)), "Not Found") -> Not Found | C36: =SUMMARY!C38 -> 0 | D36: =SUMMARY!$G$6 -> 6400 | E36: =B36*C36*(D36/1000) -> #VALUE! | F36: =$J$5 -> 675 | G36: =E36*F36 -> #VALUE!
A37: =SUMMARY!A39 -> 0 | B37: =IFERROR(INDEX('WEIGHT CATALOGUE'!D:D, MATCH(A37,'WEIGHT CATALOGUE'!B:B, 0)), "Not Found") -> Not Found | C37: =SUMMARY!C39 -> 0 | D37: =SUMMARY!$G$6 -> 6400 | E37: =B37*C37*(D37/1000) -> #VALUE! | F37: =$J$5 -> 675 | G37: =E37*F37 -> #VALUE!
A38: =SUMMARY!A40 -> 0 | B38: =IFERROR(INDEX('WEIGHT CATALOGUE'!D:D, MATCH(A38,'WEIGHT CATALOGUE'!B:B, 0)), "Not Found") -> Not Found | C38: =SUMMARY!C40 -> 0 | D38: =SUMMARY!$G$6 -> 6400 | E38: =B38*C38*(D38/1000) -> #VALUE! | F38: =$J$5 -> 675 | G38: =E38*F38 -> #VALUE!
... A45: =SUMMARY!A47 -> 0 | B45: =IFERROR(INDEX('WEIGHT CATALOGUE'!D:D, MATCH(A45,'WEIGHT CATALOGUE'!B:B, 0)), "Not Found") -> Not Found | C45: =SUMMARY!C47 -> 0 | D45: =SUMMARY!$G$6 -> 6400 | E45: =B45*C45*(D45/1000) -> #VALUE! | F45: =$J$5 -> 675 | G45: =E45*F45 -> #VALUE!
D46: TOTAL WEIGHT | E46: =_xlfn.AGGREGATE(9,6,E5:E45) -> 0 | F46: TOTAL COST | G46: =_xlfn.AGGREGATE(9,6,G5:G45) -> 0

Sheet LPO
A2: PURCHASE ORDER
A4: ALI FABRICATION SOLUTIONS LTD
A5: 21, FORTIS INDSUTRIAL PARK, SYOKIMAU
A6: Nairobi, Kenya. | D6: DATE | E6: =TODAY() -> 46082
A7: +254 707 020 989 | D7: PO # | E7: 03102501
A8: INFO.ALIFAB@GMAIL.COM
A10: VENDOR | C10: ATTN:
A11: M/S ALUMETAL COATINGS LTD | C11: AVKASH / JACOB / PANKAJ
A18: QTY | B18: PROFILE | C18: LENGTH | D18: UNIT PRICE | E18: TOTAL
A19: [LENGTHS]
A20: OWNERS SECTIONS TO POWDERCOAT | C20: =CUT_LIST!B3 -> 0
A21: =IF(AND('PROFILE COST'!C5<>"",'PROFILE COST'!C5<>0),'PROFILE COST'!C5,"") | B21: =IF(AND('PROFILE COST'!A5<>"",'PROFILE COST'!A5<>0),'PROFILE COST'!A5,"") | C21: =IF(AND('PROFILE COST'!D5<>"",'PROFILE COST'!D5<>0),'PROFILE COST'!D5,"") -> 6400
A22: =IF(AND('PROFILE COST'!C6<>"",'PROFILE COST'!C6<>0),'PROFILE COST'!C6,"") | B22: =IF(AND('PROFILE COST'!A6<>"",'PROFILE COST'!A6<>0),'PROFILE COST'!A6,"") | C22: =IF(AND('PROFILE COST'!D6<>"",'PROFILE COST'!D6<>0),'PROFILE COST'!D6,"") -> 6400
A23: =IF(AND('PROFILE COST'!C7<>"",'PROFILE COST'!C7<>0),'PROFILE COST'!C7,"") | B23: =IF(AND('PROFILE COST'!A7<>"",'PROFILE COST'!A7<>0),'PROFILE COST'!A7,"") | C23: =IF(AND('PROFILE COST'!D7<>"",'PROFILE COST'!D7<>0),'PROFILE COST'!D7,"") -> 6400
A24: =IF(AND('PROFILE COST'!C8<>"",'PROFILE COST'!C8<>0),'PROFILE COST'!C8,"") | B24: =IF(AND('PROFILE COST'!A8<>"",'PROFILE COST'!A8<>0),'PROFILE COST'!A8,"") | C24: =IF(AND('PROFILE COST'!D8<>"",'PROFILE COST'!D8<>0),'PROFILE COST'!D8,"") -> 6400
A25: =IF(AND('PROFILE COST'!C9<>"",'PROFILE COST'!C9<>0),'PROFILE COST'!C9,"") | B25: =IF(AND('PROFILE COST'!A9<>"",'PROFILE COST'!A9<>0),'PROFILE COST'!A9,"") | C25: =IF(AND('PROFILE COST'!D9<>"",'PROFILE COST'!D9<>0),'PROFILE COST'!D9,"") -> 6400
A26: =IF(AND('PROFILE COST'!C10<>"",'PROFILE COST'!C10<>0),'PROFILE COST'!C10,"") | B26: =IF(AND('PROFILE COST'!A10<>"",'PROFILE COST'!A10<>0),'PROFILE COST'!A10,"") | C26: =IF(AND('PROFILE COST'!D10<>"",'PROFILE COST'!D10<>0),'PROFILE COST'!D10,"") -> 6400
A27: =IF(AND('PROFILE COST'!C11<>"",'PROFILE COST'!C11<>0),'PROFILE COST'!C11,"") | B27: =IF(AND('PROFILE COST'!A11<>"",'PROFILE COST'!A11<>0),'PROFILE COST'!A11,"") | C27: =IF(AND('PROFILE COST'!D11<>"",'PROFILE COST'!D11<>0),'PROFILE COST'!D11,"") -> 6400
A28: =IF(AND('PROFILE COST'!C12<>"",'PROFILE COST'!C12<>0),'PROFILE COST'!C12,"") | B28: =IF(AND('PROFILE COST'!A12<>"",'PROFILE COST'!A12<>0),'PROFILE COST'!A12,"") | C28: =IF(AND('PROFILE COST'!D12<>"",'PROFILE COST'!D12<>0),'PROFILE COST'!D12,"") -> 6400
A29: =IF(AND('PROFILE COST'!C13<>"",'PROFILE COST'!C13<>0),'PROFILE COST'!C13,"") | B29: =IF(AND('PROFILE COST'!A13<>"",'PROFILE COST'!A13<>0),'PROFILE COST'!A13,"") | C29: =IF(AND('PROFILE COST'!D13<>"",'PROFILE COST'!D13<>0),'PROFILE COST'!D13,"") -> 6400
A30: =IF(AND('PROFILE COST'!C14<>"",'PROFILE COST'!C14<>0),'PROFILE COST'!C14,"") | B30: =IF(AND('PROFILE COST'!A14<>"",'PROFILE COST'!A14<>0),'PROFILE COST'!A14,"") | C30: =IF(AND('PROFILE COST'!D14<>"",'PROFILE COST'!D14<>0),'PROFILE COST'!D14,"") -> 6400
A31: =IF(AND('PROFILE COST'!C15<>"",'PROFILE COST'!C15<>0),'PROFILE COST'!C15,"") | B31: =IF(AND('PROFILE COST'!A15<>"",'PROFILE COST'!A15<>0),'PROFILE COST'!A15,"") | C31: =IF(AND('PROFILE COST'!D15<>"",'PROFILE COST'!D15<>0),'PROFILE COST'!D15,"") -> 6400
A32: =IF(AND('PROFILE COST'!C16<>"",'PROFILE COST'!C16<>0),'PROFILE COST'!C16,"") | B32: =IF(AND('PROFILE COST'!A16<>"",'PROFILE COST'!A16<>0),'PROFILE COST'!A16,"") | C32: =IF(AND('PROFILE COST'!D16<>"",'PROFILE COST'!D16<>0),'PROFILE COST'!D16,"") -> 6400
... A40: =IF(AND('PROFILE COST'!C24<>"",'PROFILE COST'!C24<>0),'PROFILE COST'!C24,"") | B40: =IF(AND('PROFILE COST'!A24<>"",'PROFILE COST'!A24<>0),'PROFILE COST'!A24,"") | C40: =IF(AND('PROFILE COST'!D24<>"",'PROFILE COST'!D24<>0),'PROFILE COST'!D24,"") -> 6400
A41: =IF(AND('PROFILE COST'!C25<>"",'PROFILE COST'!C25<>0),'PROFILE COST'!C25,"") | C41: =IF(AND('PROFILE COST'!D25<>"",'PROFILE COST'!D25<>0),'PROFILE COST'!D25,"")
A42: =IF(AND('PROFILE COST'!C26<>"",'PROFILE COST'!C26<>0),'PROFILE COST'!C26,"") | B42: =IF(AND('PROFILE COST'!A26<>"",'PROFILE COST'!A26<>0),'PROFILE COST'!A26,"") | C42: =IF(AND('PROFILE COST'!D26<>"",'PROFILE COST'!D26<>0),'PROFILE COST'!D26,"") -> 6400
A43: =IF(AND('PROFILE COST'!C27<>"",'PROFILE COST'!C27<>0),'PROFILE COST'!C27,"") | B43: =IF(AND('PROFILE COST'!A27<>"",'PROFILE COST'!A27<>0),'PROFILE COST'!A27,"") | C43: =IF(AND('PROFILE COST'!D27<>"",'PROFILE COST'!D27<>0),'PROFILE COST'!D27,"") -> 6400
A44: =IF(AND('PROFILE COST'!C28<>"",'PROFILE COST'!C28<>0),'PROFILE COST'!C28,"") | B44: =IF(AND('PROFILE COST'!A28<>"",'PROFILE COST'!A28<>0),'PROFILE COST'!A28,"") | C44: =IF(AND('PROFILE COST'!D28<>"",'PROFILE COST'!D28<>0),'PROFILE COST'!D28,"") -> 6400
A45: =IF(AND('PROFILE COST'!C29<>"",'PROFILE COST'!C29<>0),'PROFILE COST'!C29,"") | B45: =IF(AND('PROFILE COST'!A29<>"",'PROFILE COST'!A29<>0),'PROFILE COST'!A29,"") | C45: =IF(AND('PROFILE COST'!D29<>"",'PROFILE COST'!D29<>0),'PROFILE COST'!D29,"") -> 6400
A46: =IF(AND('PROFILE COST'!C30<>"",'PROFILE COST'!C30<>0),'PROFILE COST'!C30,"") | B46: =IF(AND('PROFILE COST'!A30<>"",'PROFILE COST'!A30<>0),'PROFILE COST'!A30,"") | C46: =IF(AND('PROFILE COST'!D30<>"",'PROFILE COST'!D30<>0),'PROFILE COST'!D30,"") -> 6400
A47: =IF(AND('PROFILE COST'!C31<>"",'PROFILE COST'!C31<>0),'PROFILE COST'!C31,"") | B47: =IF(AND('PROFILE COST'!A31<>"",'PROFILE COST'!A31<>0),'PROFILE COST'!A31,"") | C47: =IF(AND('PROFILE COST'!D31<>"",'PROFILE COST'!D31<>0),'PROFILE COST'!D31,"") -> 6400
A48: =IF(AND('PROFILE COST'!C32<>"",'PROFILE COST'!C32<>0),'PROFILE COST'!C32,"") | B48: =IF(AND('PROFILE COST'!A32<>"",'PROFILE COST'!A32<>0),'PROFILE COST'!A32,"") | C48: =IF(AND('PROFILE COST'!D32<>"",'PROFILE COST'!D32<>0),'PROFILE COST'!D32,"") -> 6400
A49: =IF(AND('PROFILE COST'!C33<>"",'PROFILE COST'!C33<>0),'PROFILE COST'!C33,"") | B49: =IF(AND('PROFILE COST'!A33<>"",'PROFILE COST'!A33<>0),'PROFILE COST'!A33,"") | C49: =IF(AND('PROFILE COST'!D33<>"",'PROFILE COST'!D33<>0),'PROFILE COST'!D33,"") -> 6400
A50: =IF(AND('PROFILE COST'!C34<>"",'PROFILE COST'!C34<>0),'PROFILE COST'!C34,"") | B50: =IF(AND('PROFILE COST'!A34<>"",'PROFILE COST'!A34<>0),'PROFILE COST'!A34,"") | C50: =IF(AND('PROFILE COST'!D34<>"",'PROFILE COST'!D34<>0),'PROFILE COST'!D34,"") -> 6400
A51: =IF(AND('PROFILE COST'!C35<>"",'PROFILE COST'!C35<>0),'PROFILE COST'!C35,"") | B51: =IF(AND('PROFILE COST'!A35<>"",'PROFILE COST'!A35<>0),'PROFILE COST'!A35,"") | C51: =IF(AND('PROFILE COST'!D35<>"",'PROFILE COST'!D35<>0),'PROFILE COST'!D35,"") -> 6400
A52: =IF(AND('PROFILE COST'!C36<>"",'PROFILE COST'!C36<>0),'PROFILE COST'!C36,"") | B52: =IF(AND('PROFILE COST'!A36<>"",'PROFILE COST'!A36<>0),'PROFILE COST'!A36,"") | C52: =IF(AND('PROFILE COST'!D36<>"",'PROFILE COST'!D36<>0),'PROFILE COST'!D36,"") -> 6400
A53: =IF(AND('PROFILE COST'!C37<>"",'PROFILE COST'!C37<>0),'PROFILE COST'!C37,"") | B53: =IF(AND('PROFILE COST'!A37<>"",'PROFILE COST'!A37<>0),'PROFILE COST'!A37,"") | C53: =IF(AND('PROFILE COST'!D37<>"",'PROFILE COST'!D37<>0),'PROFILE COST'!D37,"") -> 6400
... A61: =IF(AND('PROFILE COST'!C45<>"",'PROFILE COST'!C45<>0),'PROFILE COST'!C45,"") | B61: =IF(AND('PROFILE COST'!A45<>"",'PROFILE COST'!A45<>0),'PROFILE COST'!A45,"") | C61: =IF(AND('PROFILE COST'!D45<>"",'PROFILE COST'!D45<>0),'PROFILE COST'!D45,"") -> 6400
A62: =IF(AND('PROFILE COST'!C46<>"",'PROFILE COST'!C46<>0),'PROFILE COST'!C46,"") | B62: =IF(AND('PROFILE COST'!A46<>"",'PROFILE COST'!A46<>0),'PROFILE COST'!A46,"")
A63: =SUM(A21:A62) -> 0
...

Sheet WEIGHT CATALOGUE
A1: IMAGE | B1: PROFILE | C1: DESCRIPTION | D1: KG/M
B2: 75MM X 25MM BOX | C2: BOX | D2: 0.64
B3: 75MM X 45MM BOX | C3: BOX | D3: 0.76
B4: 100MM X 25MM BOX | C4: BOX | D4: 1.21
B5: 100MM X 100MM BOX | C5: BOX | D5: 3.39
B6: GDIL 6001 | C6: OUTERFRAME | D6: 1.39
B7: GDIL 6013 | C7: TRANSOM | D7: 0.75
B8: GDIL 6005 | C8: VENT | D8: 0.96
B9: GDIL 6015 | C9: BIG TRANSOM | D9: 1.03
B10: GDIL 6003 | C10: BEADING | D10: 0.34
B11: 79-030 | C11: BEADING | D11: 0.23
B12: 79-015 | C12: OUTERFRAME | D12: 0.93
B13: 79-017 | C13: TRANSOM/VENT | D13: 1.06
... B18: GDIL 4060 | C18: TRANSOM | D18: 0.92
B19: GDIL 4103 | C19: CORNER SECTION
B20: 06-001 | C20: JAMB | D20: 0.25
B21: 01-150 | C21: LOVRE | D21: 0.3
B22: 01-183 | C22: FLYSCREEN | D22: 0.25
B23: GDIL 3201 | C23: CORNER SECTION | D23: 0.29
B24: GDIL 3205 | C24: CORNER SECTION | D24: 1.17
B25: 09-001 | C25: OUTERFEAME | D25: 0.61
B26: 09-002 | C26: VENT / TRANSOM | D26: 0.67
B27: 01-231 | C27: BEADING | D27: 0.25
B28: 13-024 | C28: SMALL OUTERFRAME | D28: 0.68
B29: 13-021 | C29: VENT | D29: 0.88
B30: 13-025 | C30: TRANSOM | D30: 0.83
B31: 13-017 | C31: BEADING | D31: 0.32
... B39: 01-194 | C39: COVER PLATE | D39: 0.38
B40: GDIL 9572 | C40: PRESSURE PLATE ADAPTER
B41: M9241 | C41: OUTERFRAME | D41: 1.52
B42: M9292 | C42: SASH | D42: 1.23
B43: M9233 | C43: INTERLOCK | D43: 0.76
B44: M14650 | C44: 2 TRACK OUTER | D44: 1.62
B45: 250-139 | C45: 2 TRACK OUTER | D45: 1.62
B46: M14627 | C46: 3 TRACK OUTER | D46: 2
B47: 250-140 | C47: 3 TRACK OUTER | D47: 2
B48: M14632 | C48: SASH | D48: 0.96
B49: 250-133 | C49: SASH | D49: 0.96
B50: M14614 | C50: ADJOINING | D50: 0.85
B51: 250-141 | C51: ADJOINING | D51: 0.85
...

Sheet PROFILE SIZE CALCULATOR
A2: GDIL 6001 - PROJECTING WINDOW | P2: 16-086 - PROJECTING WINDOW | AE2: 13-024- PROJECTING WINDOW | AT2: 09-001- PROJECTING WINDOW | BI2: GDIL 4054- PROJECTING WINDOW | BX2: M14650 - SLIDING DOOR / WINDOW | CN2: M14627 - 3 TRACK SLIDING DOOR / WINDOW | DD2: M9241 - SLIDING DOOR / WINDOW | DT2: M9838 - SLIDING FOLDING DOORS | EH2: 79-015 SWING DOOR | EV2: GDIL 6001 SWING DOOR
CG4: OVERALL SIZE | CJ4: GLASS SIZES | CW4: OVERALL SIZE | CZ4: GLASS SIZES | DM4: OVERALL SIZE | DP4: GLASS SIZES | EA4: OVERALL SIZE | ED4: GLASS SIZES | EO4: OVERALL SIZE | ER4: GLASS SIZES | FC4: OVERALL SIZE | FF4: GLASS SIZES
I5: WINDOW SIZE | L5: GLASS SIZES | X5: WINDOW SIZE | AA5: GLASS SIZES | AM5: WINDOW SIZE | AP5: GLASS SIZES | BB5: WINDOW SIZE | BE5: GLASS SIZES | BQ5: WINDOW SIZE | BT5: GLASS SIZES | CG5: OVERALL WIDTH | CJ5: WIDTH | CK5: HEIGHT | CL5: QUANTITY | CW5: OVERALL WIDTH | CZ5: WIDTH | DA5: HEIGHT | DB5: QUANTITY | DM5: OVERALL WIDTH | DP5: WIDTH | DQ5: HEIGHT | DR5: QUANTITY | EA5: OVERALL WIDTH | ED5: WIDTH | EE5: HEIGHT | EF5: QUANTITY | EO5: OVERALL WIDTH | ER5: WIDTH | ES5: HEIGHT | ET5: QUANTITY | FC5: OVERALL WIDTH | FF5: WIDTH | FG5: HEIGHT | FH5: QUANTITY
I6: OVERALL WIDTH | L6: WIDTH | M6: HEIGHT | N6: QUANTITY | X6: OVERALL WIDTH | AA6: WIDTH | AB6: HEIGHT | AC6: QUANTITY | AM6: OVERALL WIDTH | AP6: WIDTH | AQ6: HEIGHT | AR6: QUANTITY | BB6: OVERALL WIDTH | BE6: WIDTH | BF6: HEIGHT | BG6: QUANTITY | BQ6: OVERALL WIDTH | BT6: WIDTH | BU6: HEIGHT | BV6: QUANTITY | CG6: OVERALL HEIGHT | CJ6: =CH12-134 -> -121.5 | CK6: =CH13-134 -> -202 | CL6: =CI12/2 -> 2 | CW6: OVERALL HEIGHT | CZ6: =CX12-134 -> -121.5 | DA6: =CX13-134 -> -194 | DB6: =CY12/2-1 -> 2 | DM6: OVERALL HEIGHT | DP6: =DN12-134 -> -131 | DQ6: =DN13-134 -> -199 | DR6: =DO12/2 -> 2 | EA6: OVERALL HEIGHT | ED6: =EB15-6 -> -112 | EE6: =EB16-6 -> -184.5 | EF6: =EC13/2 -> 3 | EO6: OVERALL HEIGHT | ER6: =EP15-6 -> -152 | ES6: =EP16-6 -> -126 | ET6: =EQ15/2 -> 1 | FC6: OVERALL HEIGHT | FF6: =FD15-6 -> -114 | FG6: =FD16-6 -> -93 | FH6: =FE15/2 -> 1
I7: OVERALL HEIGHT | L7: =J19-6 -> -118 | M7: =J20-6 -> -93 | N7: =K19/2 -> 2 | X7: OVERALL HEIGHT | AA7: =Y19-6 -> -148 | AB7: =Y20-6 -> -123 | AC7: =Z19/2 -> 2 | AM7: OVERALL HEIGHT | AP7: =AN19-6 -> -148 | AQ7: =AN20-6 -> -123 | AR7: =AO19/2 -> 2 | BB7: OVERALL HEIGHT | BE7: =BC19-6 -> -128 | BF7: =BC20-6 -> -101 | BG7: =BD19/2 -> 2 | BQ7: OVERALL HEIGHT | BT7: =BR19-6 -> -148 | BU7: =BR20-6 -> -123 | BV7: =BS19/2 -> 2 | EO7: BOTTOM CLEARANCE REQUIRED | FC7: BOTTOM CLEARANCE REQUIRED
I8: VENT WIDTH | L8: =J21-6 -> -56 | M8: =J22-6 -> -56 | N8: =K21/2 -> 2 | X8: VENT WIDTH | AA8: =Y21-6 -> -56 | AB8: =Y22-6 -> -56 | AC8: =Z21/2 -> 2 | AM8: VENT WIDTH | AP8: =AN21-6 -> -56 | AQ8: =AN22-6 -> -56 | AR8: =AO21/2 -> 2 | BB8: VENT WIDTH | BE8: =BC21-6 -> -58 | BF8: =BC22-6 -> -56 | BG8: =BD21/2 -> 2 | BQ8: VENT WIDTH | BT8: =BR21-6 -> -56 | BU8: =BR22-6 -> -56 | BV8: =BS21/2 -> 2 | CG8: PROFILES REQUIRED | CW8: PROFILES REQUIRED | DM8: PROFILES REQUIRED | EA8: PROFILES REQUIRED
I9: BOTTOM FIXED HEIGHT | L9: =J23-6 -> -6 | M9: =J24-6 -> -56 | N9: =K23/2 -> 1 | X9: BOTTOM FIXED HEIGHT | AA9: =Y23-6 -> -6 | AB9: =Y24-6 -> -56 | AC9: =Z23/2 -> 1 | AM9: BOTTOM FIXED HEIGHT | AP9: =AN23-6 -> -6 | AQ9: =AN24-6 -> -56 | AR9: =AO23/2 -> 1 | BB9: BOTTOM FIXED HEIGHT | BE9: =BC23-6 -> -6 | BF9: =BC24-6 -> -58 | BG9: =BD23/2 -> 1 | BQ9: BOTTOM FIXED HEIGHT | BT9: =BR23-6 -> -6 | BU9: =BR24-6 -> -56 | BV9: =BS23/2 -> 1 | CG9: PROFILE | CH9: SIZE | CI9: QUANTITY | CJ9: CUT DEGREE | CW9: PROFILE | CX9: SIZE | CY9: QUANTITY | CZ9: CUT DEGREE | DM9: PROFILE | DN9: SIZE | DO9: QUANTITY | DP9: CUT DEGREE | EA9: PROFILE | EB9: SIZE | EC9: QUANTITY | ED9: CUT DEGREE | EO9: PROFILES REQUIRED | FC9: PROFILES REQUIRED
CG10: M14650 2 TRACK OUTERFRAME | CH10: =CH5 -> 0 | CI10: 2 | CJ10: 45 | CW10: M146527 3 TRACK OUTERFRAME | CX10: =CX5 -> 0 | CY10: 2 | CZ10: 45 | DM10: M9241 2 TRACK OUTERFRAME | DN10: =DN5 -> 0 | DO10: 2 | DP10: 45 | EA10: M9838 TOP RAIL | EB10: =EB5 -> 0 | EC10: 1 | ED10: 90 | EO10: PROFILE | EP10: SIZE | EQ10: QUANTITY | ER10: CUT DEGREE | FC10: PROFILE | FD10: SIZE | FE10: QUANTITY | FF10: CUT DEGREE
I11: PROFILES REQUIRED | X11: PROFILES REQUIRED | AM11: PROFILES REQUIRED | BB11: PROFILES REQUIRED | BQ11: PROFILES REQUIRED | CG11: M14650 2 TRACK OUTERFRAME | CH11: =CH6 -> 0 | CI11: 2 | CJ11: 45 | CW11: M146527 3 TRACK OUTERFRAME | CX11: =CX6 -> 0 | CY11: 2 | CZ11: 45 | DM11: M9241 2 TRACK OUTERFRAME | DN11: =DN6 -> 0 | DO11: 2 | DP11: 45 | EA11: M9847 BOTTOM RAIL | EB11: =EB5 -> 0 | EC11: 1 | ED11: 90 | EO11: 79-015 OUTERFRAME | EP11: =EP5 -> 0 | EQ11: 1 | ER11: 45 | FC11: GDIL 6001 OUTERFRAME | FD11: =FD5 -> 0 | FE11: 1 | FF11: 45
I12: PROFILE | J12: SIZE | K12: QUANTITY | L12: CUT DEGREE | X12: PROFILE | Y12: SIZE | Z12: QUANTITY | AA12: CUT DEGREE | AM12: PROFILE | AN12: SIZE | AO12: QUANTITY | AP12: CUT DEGREE | BB12: PROFILE | BC12: SIZE | BD12: QUANTITY | BE12: CUT DEGREE | BQ12: PROFILE | BR12: SIZE | BS12: QUANTITY | BT12: CUT DEGREE | CG12: M14632 SHASH | CH12: =(CH5+25)/2 -> 12.5 | CI12: 4 | CJ12: 45 | CW12: M14632 SHASH | CX12: =(CX5+25)/2 -> 12.5 | CY12: 6 | CZ12: 45 | DM12: M9292 SHASH | DN12: =(DN5+6)/2 -> 3 | DO12: 4 | DP12: 45 | EA12: M9833 JAMB | EB12: =EB6-68-21 -> -89 | EC12: 2 | ED12: 90 | EO12: 79-015 OUTERFRAME | EP12: =EP6 -> 0 | EQ12: 2 | ER12: 45 | FC12: GDIL 6001 OUTERFRAME | FD12: =FD6 -> 0 | FE12: 2 | FF12: 45
I13: GDIL 6001 OUTERFRAME | J13: =J6 -> 0 | K13: 2 | L13: 45 | X13: 16-086 OUTERFRAME | Y13: =Y6 -> 0 | Z13: 2 | AA13: 45 | AM13: 13-024 OUTERFRAME | AN13: =AN6 -> 0 | AO13: 2 | AP13: 45 | BB13: 90-001 OUTERFRAME | BC13: =BC6 -> 0 | BD13: 2 | BE13: 45 | BQ13: GDIL 4054 OUTERFRAME | BR13: =BR6 -> 0 | BS13: 2 | BT13: 45 | CG13: M14632 SHASH | CH13: =CH6-68 -> -68 | CI13: 4 | CJ13: 45 | CW13: M14632 SHASH | CX13: =CX6-60 -> -60 | CY13: 6 | CZ13: 45 | DM13: M9292 SHASH | DN13: =DN6-65 -> -65 | DO13: 4 | DP13: 45 | EA13: M9834 SASH | EB13: =(EB5-30-12-12-12-12-30)/3 -> -36 | EC13: 6 | ED13: 45 | EO13: 79-017 VENT | EP13: =EP5-60+14 -> -46 | EQ13: 2 | ER13: 45 | FC13: GDIL 6005 VENT | FD13: =FD5-50+12 -> -38 | FE13: 2 | FF13: 45
I14: GDIL 6001 OUTERFRAME | J14: =J7 -> 0 | K14: 2 | L14: 45 | X14: 16-086 OUTERFRAME | Y14: =Y7 -> 0 | Z14: 2 | AA14: 45 | AM14: 13-024 OUTERFRAME | AN14: =AN7 -> 0 | AO14: 2 | AP14: 45 | BB14: 09-001 OUTERFRAME | BC14: =BC7 -> 0 | BD14: 2 | BE14: 45 | BQ14: GDIL 4054 OUTERFRAME | BR14: =BR7 -> 0 | BS14: 2 | BT14: 45 | CG14: M14615 INTERLOCK | CH14: =CH6-68 -> -68 | CI14: 2 | CJ14: 90 | CW14: M14615 INTERLOCK | CX14: =CX6-60 -> -60 | CY14: 4 | CZ14: 90 | DM14: M9233 INTERLOCK | DN14: =DN6-65 -> -65 | DO14: 2 | DP14: 90 | EA14: M9834 SASH | EB14: =EB6-69-6-6-21-6.5 -> -108.5 | EC14: 6 | ED14: 45 | EO14: 79-017 VENT | EP14: =EP6-30-EP7+10 -> -20 | EQ14: 2 | ER14: 45 | FC14: GDIL 6005 VENT | FD14: =FD6-25-FD7+8 -> -17 | FE14: 2 | FF14: 45
I15: GDIL 6013 TRANSOM | J15: =J7-50 -> -50 | K15: 2 | L15: 90 | X15: 13-025 TRANSOM | Y15: =Y7-50 -> -50 | Z15: 2 | AA15: 90 | AM15: 13-025 TRANSOM | AN15: =AN7-50 -> -50 | AO15: 2 | AP15: 90 | BB15: 09-002 TRANSOM | BC15: =BC7-52 -> -52 | BD15: 2 | BE15: 90 | BQ15: GDIL 4060 TRANSOM | BR15: =BR7-50 -> -50 | BS15: 2 | BT15: 90 | CG15: 100-020M | CH15: =CH5 -> 0 | CI15: 1 | CJ15: 90 | CW15: 100-020M | CX15: =CX5 -> 0 | CY15: 2 | CZ15: 90 | EA15: M11453 BEADING | EB15: =EB13-70 -> -106 | EC15: 6 | ED15: 90 | EO15: 79-032 BEADING | EP15: =EP13-100 -> -146 | EQ15: 2 | ER15: 90 | FC15: GDIL 6003 BEADING | FD15: =FD13-70 -> -108 | FE15: 2 | FF15: 90
I16: GDIL 6013 TRANSOM | J16: =J8-50 -> -50 | K16: 2 | L16: 90 | X16: 13-025 TRANSOM | Y16: =Y8-50 -> -50 | Z16: 2 | AA16: 90 | AM16: 13-025 TRANSOM | AN16: =AN8-50 -> -50 | AO16: 2 | AP16: 90 | BB16: 09-002 TRANSOM | BC16: =BC8-52 -> -52 | BD16: 2 | BE16: 90 | BQ16: GDIL 4060 TRANSOM | BR16: =BR8-50 -> -50 | BS16: 2 | BT16: 90 | EA16: M11453 BEADING | EB16: =EB14-70 -> -178.5 | EC16: 6 | ED16: 90 | EO16: 79-032 BEADING | EP16: =EP14-100 -> -120 | EQ16: 2 | ER16: 90 | FC16: GDIL 6003 BEADING | FD16: =FD14-70 -> -87 | FE16: 2 | FF16: 90
I17: GDIL 6005 VENT | J17: =J16+8 -> -42 | K17: 4 | L17: 45 | X17: 13-021 VENT | Y17: =Y16+8 -> -42 | Z17: 4 | AA17: 45 | AM17: 13-021 VENT | AN17: =AN16+8 -> -42 | AO17: 4 | AP17: 45 | BB17: 09-002 VENT | BC17: =BC16+10 -> -42 | BD17: 4 | BE17: 45 | BQ17: GDIL 4056 VENT | BR17: =BR16+8 -> -42 | BS17: 4 | BT17: 45 | EA17: M9805 STOPPER | EB17: =EB6 -> 0 | EC17: 1 | ED17: 90
I18: GDIL 6005 VENT | J18: =J7-J9-25+8 -> -17 | K18: 4 | L18: 45 | X18: 13-021 VENT | Y18: =Y7-Y9-25+8 -> -17 | Z18: 4 | AA18: 45 | AM18: 13-021 VENT | AN18: =AN7-AN9-25+8 -> -17 | AO18: 4 | AP18: 45 | BB18: 09-002 VENT | BC18: =BC7-BC9-25+10 -> -15 | BD18: 4 | BE18: 45 | BQ18: GDIL 4056 VENT | BR18: =BR7-BR9-25+8 -> -17 | BS18: 4 | BT18: 45 | EA18: M9806 WOOLPHILE | EB18: =EB13 -> -36 | EC18: 6 | ED18: 90
